Workbook

Sheet 1-1.Plan
A1: Plan
C3: P/N | G3: JAN | H3: FEB | I3: MAR | J3: APR | K3: MAY | L3: JUN | M3: JUL | N3: AUG | O3: SEP | P3: OCT | Q3: NOV | R3: DEC
C4: ASSY-001 | G4: 165 | H4: 77 | I4: 202 | J4: 333 | K4: 24 | L4: 37 | M4: 274 | N4: 48 | O4: 187 | P4: 298 | Q4: 29 | R4: 259
C5: ASSY-002 | G5: 109 | H5: 19 | I5: 44 | J5: 222 | K5: 214 | L5: 35 | M5: 123 | N5: 46 | O5: 282 | P5: 217 | Q5: 30 | R5: 289
C6: ASSY-003 | G6: 63 | H6: 114 | I6: 322 | J6: 321 | K6: 298 | L6: 31 | M6: 295 | N6: 299 | O6: 203 | P6: 25 | Q6: 113 | R6: 23
C7: ASSY-004 | G7: 285 | H7: 68 | I7: 148 | J7: 214 | K7: 73 | L7: 276 | M7: 60 | N7: 292 | O7: 157 | P7: 286 | Q7: 349 | R7: 92
C8: ASSY-005 | G8: 52 | H8: 297 | I8: 292 | J8: 327 | K8: 96 | L8: 190 | M8: 49 | N8: 280 | O8: 364 | P8: 32 | Q8: 288 | R8: =#N/A -> #N/A
C9: ASSY-006 | G9: 316 | H9: 105 | I9: 254 | J9: 348 | K9: 272 | L9: 218 | M9: 397 | N9: 160 | O9: 238 | P9: 299 | Q9: 232 | R9: 185
C10: ASSY-007 | G10: 153 | H10: 127 | I10: n/a | J10: 357 | K10: 399 | L10: 124 | M10: 41 | N10: 294 | O10: 153 | P10: 268 | Q10: 253 | R10: 175
C11: ASSY-008 | G11: 373 | H11: 229 | I11: 147 | J11: 311 | K11: 37 | L11: 60 | M11: 262 | N11: 214 | O11: 84 | P11: 387 | Q11: 175 | R11: 77
C12: ASSY-009 | G12: 250 | H12: 215 | I12: 20 | J12: 342 | K12: 39 | L12: 391 | M12: 285 | N12: 293 | O12: 160 | P12: 174 | Q12: 355 | R12: 179
C13: ASSY-010 | G13: 304 | H13: 254 | I13: 296 | J13: 233 | K13: 35 | L13: 47 | M13: 138 | N13: 242 | O13: 356 | P13: 340 | Q13: 33 | R13: 31
C14: ASSY-011 | G14: 374 | H14: 359 | I14: 158 | J14: 331 | K14: 295 | L14: 348 | M14: 228 | N14: 145 | O14: 366 | P14: 197 | Q14: 342 | R14: 177
C15: ASSY-012 | G15: 11 | H15: 236 | I15: 181 | J15: 86 | K15: 312 | L15: 59 | M15: 252 | N15: 30 | O15: 111 | P15: 393 | Q15: 147 | R15: 66
C16: ASSY-013 | G16: 378 | H16: 126 | I16: 203 | J16: 200 | K16: 254 | L16: 41 | M16: 85 | N16: 229 | O16: 205 | P16: 281 | Q16: 142 | R16: 70
C17: ASSY-014 | G17: 220 | H17: 281 | I17: 142 | J17: 361 | K17: 212 | L17: 183 | M17: 349 | N17: 194 | O17: 118 | P17: 77 | Q17: 42 | R17: 90
C18: ASSY-015 | G18: 77 | H18: 118 | I18: 337 | J18: 119 | K18: 6 | L18: 248 | M18: 301 | N18: 93 | O18: 134 | P18: 144 | Q18: 2 | R18: 74
C19: ASSY-016 | G19: 214 | H19: 273 | I19: 189 | J19: 312 | K19: 289 | L19: 163 | M19: 64 | N19: 353 | O19: 263 | P19: 316 | Q19: 335 | R19: 346
C20: ASSY-017 | G20: 378 | H20: 27 | I20: 233 | J20: 399 | K20: 348 | L20: 286 | M20: 200 | N20: 203 | O20: 204 | P20: 201 | Q20: 53 | R20: 246
C21: ASSY-018 | G21: 324 | H21: 205 | I21: 31 | J21: 97 | K21: 34 | L21: 106 | M21: 225 | N21: 83 | O21: 56 | P21: 174 | Q21: 307 | R21: 26
C22: ASSY-019 | G22: 52 | H22: 0 | I22: 290 | J22: 77 | K22: 274 | L22: 51 | M22: 186 | N22: 314 | O22: 13 | P22: 36 | Q22: 106 | R22: 314
... C35: assy-002 | G35: 10 | H35: 10 | I35: 10 | J35: 10 | K35: 10 | L35: 10 | M35: 10 | N35: 10 | O35: 10 | P35: 10 | Q35: 10 | R35: 10
C36: 12345 | G36: 28 | H36: 4 | I36: 33 | J36: 28 | K36: 38 | L36: 65 | M36: 31 | N36: 76 | O36: 42 | P36: 34 | Q36: 70 | R36: 54
G37: 99 | H37: 99 | I37: 99 | J37: 99 | K37: 99 | L37: 99 | M37: 99 | N37: 99 | O37: 99 | P37: 99 | Q37: 99 | R37: 99

Sheet PART METHOD
A1: Parts made by another method (read by CAPA_Recalc)
A4: FMCNC1 machines = sheet 1-3 rows with Kind (column B): | D4: FMCNC1 | E4: 7
A5: HAND machines = sheet 1-3 rows with Kind (column B): | D5: HAND
A6: FMCNC2 machines = sheet 1-3 rows with Kind (column B): | D6: FMCNC2 | E6: 7.5
A7: Child P/N | B7: Shop (FM / BD) | C7: Method | D7: Time
A8: CH-001 | B8: FM | C8: FMCNC1
A9: CH-002 | B9: FM | C9: FMCNC2 | D9: 5
A10: CH-003 | B10: BD | C10: HAND | D10: 12
A11: CH-004 | B11: BD | C11: HAND
A12: CH-005 | B12: FM | C12: CNC2
A13: CH-006 | B13: BD | C13: MANUAL | D13: 9
A14: CH-007 | B14: FM | C14: fmcnc 1
A15: CH-099 | B15: FM | C15: FMCNC1
A16: CH-008 | B16: FM | C16: XYZ
A17: CH-002 | B17: BD | C17: HAND

Sheet 1-2.ITEM
A1: ST table
CI3: 1 | CJ3: 1 | CK3: 1 | CL3: 1 | CM3: 0.9 | CN3: 1 | CO3: 1.25 | CP3: 1 | CQ3: 1.1 | CR3: 1 | CS3: 1 | CT3: 1.25 | CU3: 0.9 | CV3: 1 | CW3: 1 | CX3: 1 | CY3: 1 | CZ3: 1 | DA3: 1 | DB3: 1 | DC3: 1 | DD3: 1 | DE3: 1 | DF3: 1 | DG3: 1 | DH3: 1 | DI3: 1 | DJ3: 1.25 | DK3: 1 | DL3: 1.1 | DM3: 1 | DN3: 1 | DO3: 1.1 | DP3: 1 | DQ3: 1 | DR3: 1 | DS3: 1 | DT3: 1.25 | DU3: 1 | DV3: 1 | DW3: 1 | DX3: 1 | DY3: 1 | DZ3: 1 | EA3: 1 | EB3: 1 | EC3: 1 | ED3: 1.25 | EE3: 1 | EF3: 1.1 | EG3: 1 | EH3: 1.25 | EI3: 1 | EJ3: 1 | EK3: 1.25 | EL3: 1 | EM3: 1 | EN3: 1 | EO3: 1 | EP3: 1 | EQ3: 1 | ER3: 1.25 | ES3: 1 | ET3: 1 | EU3: 1.25 | EW3: 1 | EX3: 1 | EY3: 1 | EZ3: 1 | FA3: 1.25 | FB3: 1 | FC3: 1 | FD3: 1 | FE3: 0.9 | FF3: 1 | FG3: 1 | FH3: 1 | FI3: 1 | FJ3: 1.25 | FK3: 1 | FL3: 1 | FM3: 1 | FN3: 1 | FO3: 0.9 | FP3: 0.9 | FQ3: 1 | FR3: 1 | FS3: 1.25 | FT3: 1 | FU3: 0.9 | FV3: 1 | FW3: 1 | FX3: 0.9 | FY3: 1.25 | FZ3: 1.1 | GA3: 1.1 | GB3: 1 | GC3: 1 | GD3: 1 | GE3: 1 | GF3: 1 | GG3: 1 | GH3: 1 | GI3: 1 | GJ3: 1 | GK3: 1 | GL3: 1 | GM3: 1 | GN3: 1.25 | GO3: 0.9 | GP3: 1.1 | GQ3: 1 | GR3: 1 | GS3: 1.25 | GT3: 1 | GU3: 1 | GV3: 1 | GW3: 1.25 | GX3: 1.1 | GY3: 1 | GZ3: 1 | HA3: 1.1 | HB3: 1.25 | HC3: 1 | HD3: 1 | HE3: 1 | HF3: 1.25 | HG3: 1 | HH3: 1 | HI3: 1 | HK3: 1.1 | HL3: 1 | HM3: 1.1 | HN3: 1 | HO3: 1 | HP3: 1 | HQ3: 1 | HR3: 1.1 | HS3: 1 | HT3: 0.9 | HU3: 1.1 | HV3: 1 | HW3: 1.25 | HX3: 1.1 | HY3: 1 | HZ3: 1 | IA3: 1.25 | IB3: 1.1 | IC3: 1 | ID3: 1.25 | IE3: 1 | IF3: 1 | IG3: 1.25 | IH3: 1.1 | II3: 1 | IJ3: 1 | IK3: 1 | IL3: 1 | IM3: 1 | IN3: 1.25 | IO3: 1 | IP3: 1 | IQ3: 1 | IR3: 1.25 | IS3: 0.9 | IT3: 0.9 | IU3: 1.1 | IV3: 1 | IW3: 1 | IX3: 1 | IY3: 1 | IZ3: 1 | JA3: 1 | JB3: 1.25 | JC3: 1 | JD3: 1.1 | JE3: 1 | JF3: 1 | JG3: 1 | JH3: 0.9 | JI3: 1 | JJ3: 1.25 | JK3: 1 | JL3: 1 | JM3: 1.1 | JN3: 1 | JO3: 1 | JP3: 1.25 | JQ3: 1 | JR3: 1 | JS3: 1 | JT3: 1 | JU3: 1.1 | JV3: 1 | JW3: 1 | JY3: 1 | JZ3: 1 | KA3: 1.25 | KB3: 1.25 | KC3: 1 | KD3: 1 | KE3: 1.25 | KF3: 1 | KG3: 0.9 | KH3: 1.1 | KI3: 0.9 | KJ3: 1 | KK3: 1 | KL3: 1 | KM3: 1 | KN3: 1.1 | KO3: 1.25 | KP3: 1.1 | KQ3: 1 | KR3: 1.25 | KS3: 1 | KT3: 1 | KU3: 1 | KV3: 1 | KW3: 1 | KX3: 1.25 | KY3: 1 | KZ3: 1 | LA3: 1.1 | LB3: 1 | LC3: 1 | LD3: 1 | LE3: 1.1 | LF3: 1 | LG3: 1 | LH3: 1 | LI3: 1 | LJ3: 1 | LK3: 1 | LL3: 1 | LM3: 1 | LN3: 1 | LO3: 1 | LP3: 1 | LQ3: 1.1 | LR3: 1 | LS3: 1 | LT3: 1 | LU3: 1 | LV3: 1 | LW3: 1 | LX3: 1 | LY3: 1 | LZ3: 0.9 | MA3: 1.25 | MB3: 1 | MC3: 0.9 | MD3: 1 | ME3: 1 | MF3: 1 | MG3: 1 | MH3: 1 | MI3: 0.9 | MJ3: 1.25 | MK3: 0.9 | MM3: 0.9 | MN3: 1 | MO3: 1.1 | MP3: 1 | MQ3: 1 | MR3: 1 | MS3: 1 | MT3: 1 | MU3: 1.1 | MV3: 1.1 | MW3: 1 | MX3: 1 | MY3: 1.1 | MZ3: 0.9 | NA3: 1.1 | NB3: 1 | NC3: 1.25 | ND3: 1 | NE3: 1 | NF3: 1 | NG3: 1 | NH3: 1 | NI3: 1 | NJ3: 1 | NK3: 0.9 | NL3: 0.9 | NM3: 1 | NN3: 1 | NO3: 0.9 | NP3: 0.9 | NQ3: 1 | NR3: 1 | NS3: 1 | NT3: 0.9 | NU3: 1 | NV3: 1.25 | NW3: 1.25 | NX3: 0.9 | NY3: 1 | NZ3: 1 | OA3: 1 | OB3: 1.1 | OC3: 1 | OD3: 0.9 | OE3: 1 | OF3: 1 | OG3: 1.25 | OH3: 1 | OI3: 1.1 | OJ3: 1 | OK3: 1 | OL3: 1 | OM3: 0.9 | ON3: 1 | OO3: 0.9 | OP3: 1 | OQ3: 1 | OR3: 1 | OS3: 1 | OT3: 1 | OU3: 1 | OV3: 1 | OW3: 0.9 | OX3: 0.9 | OY3: 1 | PA3: 0.9 | PB3: 1 | PC3: 1 | PD3: 1 | PE3: 1.1 | PF3: 1 | PG3: 1.1 | PH3: 1 | PI3: 1 | PJ3: 1 | PK3: 1 | PL3: 1 | PM3: 1 | PN3: 0.9 | PO3: 1 | PP3: 1 | PQ3: 1 | PR3: 1 | PS3: 1 | PT3: 1.1 | PU3: 1 | PV3: 1.25 | PW3: 1 | PX3: 1 | PY3: 1.25 | PZ3: 1 | QA3: 1 | QB3: 1 | QC3: 1.25 | QD3: 1 | QE3: 1 | QF3: 0.9 | QG3: 1 | QH3: 1 | QI3: 1.1 | QJ3: 0.9 | QK3: 1 | QL3: 1.1 | QM3: 1.1 | QN3: 1 | QO3: 1.1 | QP3: 1 | QQ3: 1 | QR3: 1.1 | QS3: 1.1 | QT3: 0.9 | QU3: 1 | QV3: 1 | QW3: 1 | QX3: 1.25 | QY3: 1 | QZ3: 1 | RA3: 1 | RB3: 0.9 | RC3: 1 | RD3: 1 | RE3: 1 | RF3: 1 | RG3: 0.9 | RH3: 1 | RI3: 1 | RJ3: 1 | RK3: 1.25 | RL3: 1 | RM3: 1.1 | RO3: 1 | RP3: 1 | RQ3: 1 | RR3: 0.9 | RS3: 1 | RT3: 1 | RU3: 1 | RV3: 1 | RW3: 0.9 | RX3: 0.9 | RY3: 1 | RZ3: 1 | SA3: 1 | SB3: 1 | SC3: 1.1 | SD3: 1 | SE3: 1.25 | SF3: 1 | SG3: 1 | SH3: 1 | SI3: 1 | SJ3: 1 | SK3: 1 | SL3: 1 | SM3: 1 | SN3: 1 | SO3: 1 | SP3: 1 | SQ3: 1 | SR3: 1 | SS3: 1.25 | ST3: 1 | SU3: 1 | SV3: 1 | SW3: 1 | SX3: 0.9 | SY3: 1 | SZ3: 1.1 | TA3: 1 | TB3: 1 | TC3: 1 | TD3: 1 | TE3: 1 | TF3: 1 | TG3: 1.25 | TH3: 1.1 | TI3: 1 | TJ3: 1 | TK3: 1.25 | TL3: 1 | TM3: 1 | TN3: 1 | TO3: 1 | TP3: 1 | TQ3: 1 | TR3: 1.25 | TS3: 1 | TT3: 0.9 | TU3: 1 | TV3: 1 | TW3: 1 | TX3: 1 | TY3: 1 | TZ3: 1 | UA3: 1 | UC3: 1 | UD3: 1 | UE3: 1.1 | UF3: 1 | UG3: 1 | UH3: 1 | UI3: 1 | UJ3: 1.1 | UK3: 1 | UL3: 1.1 | UM3: 1 | UN3: 1 | UO3: 1 | UP3: 1 | UQ3: 1.25 | UR3: 0.9 | US3: 1 | UT3: 1 | UU3: 1 | UV3: 1 | UW3: 1.1 | UX3: 0.9 | UY3: 1 | UZ3: 0.9 | VA3: 1 | VB3: 1 | VC3: 0.9 | VD3: 1 | VE3: 1 | VF3: 1 | VG3: 0.9 | VH3: 1 | VI3: 1 | VJ3: 1 | VK3: 1 | VL3: 1 | VM3: 1 | VN3: 1 | VO3: 0.9 | VP3: 1 | VQ3: 1 | VR3: 1 | VS3: 1.25 | VT3: 0.9 | VU3: 1 | VV3: 1 | VW3: 1 | VX3: 1 | VY3: 1 | VZ3: 1 | WA3: 1 | WB3: 1 | WC3: 1 | WD3: 1 | WE3: 1.25 | WF3: 1 | WG3: 1 | WH3: 1.25 | WI3: 0.9 | WJ3: 1 | WK3: 1.1 | WL3: 1 | WM3: 1 | WN3: 1 | WO3: 1 | WQ3: 1 | WR3: 0.9 | WS3: 1 | WT3: 1 | WU3: 1 | WV3: 1 | WW3: 1 | WX3: 1 | WY3: 1 | WZ3: 1 | XA3: 1 | XB3: 1 | XC3: 1 | XD3: 1 | XE3: 1 | XF3: 1 | XG3: 1 | XH3: 1 | XI3: 1.25 | XJ3: 1 | XK3: 1.1 | XL3: 1 | XM3: 1 | XN3: 1 | XO3: 1 | XP3: 1 | XQ3: 1 | XR3: 1 | XS3: 1.25 | XT3: 0.9 | XU3: 1 | XV3: 0.9 | XW3: 1 | XX3: 0.9 | XY3: 1 | XZ3: 1 | YA3: 1.25 | YB3: 1 | YC3: 1.25 | YD3: 1 | YE3: 1 | YF3: 0.9 | YG3: 1 | YH3: 1 | YI3: 1 | YJ3: 0.9 | YK3: 1 | YL3: 1 | YM3: 0.9 | YN3: 1 | YO3: 1 | YP3: 0.9 | YQ3: 1 | YR3: 1 | YS3: 1.1 | YT3: 0.9 | YU3: 1 | YV3: 1 | YW3: 1 | YX3: 0.9 | YY3: 1.25 | YZ3: 1.1 | ZA3: 1.25 | ZB3: 1 | ZC3: 1 | ZE3: 1 | ZF3: 1 | ZG3: 1 | ZH3: 1 | ZI3: 0.9 | ZJ3: 1 | ZK3: 1 | ZL3: 1.1 | ZM3: 1 | ZN3: 1 | ZO3: 1 | ZP3: 1 | ZQ3: 1.25 | ZR3: 1 | ZS3: 1 | ZT3: 0.9 | ZU3: 1 | ZV3: 1 | ZW3: 1 | ZX3: 0.9 | ZY3: 1 | ZZ3: 0.9 | AAA3: 1 | AAB3: 1.1 | AAC3: 1.25 | AAD3: 0.9 | AAE3: 0.9 | AAF3: 1.25 | AAG3: 1 | AAH3: 1 | AAI3: 1.1 | AAJ3: 1.25 | AAK3: 1 | AAL3: 1 | AAM3: 1 | AAN3: 1 | AAO3: 1 | AAP3: 1 | AAQ3: 1 | AAR3: 1 | AAS3: 1 | AAT3: 1.25 | AAU3: 1 | AAV3: 1 | AAW3: 1 | AAX3: 1 | AAY3: 1 | AAZ3: 1.25 | ABA3: 1 | ABB3: 1.1 | ABC3: 1 | ABD3: 1 | ABE3: 1 | ABF3: 1.25 | ABG3: 0.9 | ABH3: 1 | ABI3: 1 | ABJ3: 0.9 | ABK3: 1 | ABL3: 1.1 | ABM3: 1 | ABN3: 1 | ABO3: 1.25 | ABP3: 1 | ABQ3: 1 | ABS3: 1.25 | ABT3: 1 | ABU3: 0.9 | ABV3: 1 | ABW3: 1.1 | ABX3: 1 | ABY3: 1 | ABZ3: 1 | ACA3: 1 | ACB3: 1 | ACC3: 1.1 | ACD3: 1 | ACE3: 1 | ACF3: 1.25 | ACG3: 1 | ACH3: 1 | ACI3: 0.9 | ACJ3: 1.1 | ACK3: 1.1 | ACL3: 1.25 | ACM3: 1 | ACN3: 1.25 | ACO3: 1 | ACP3: 1 | ACQ3: 1 | ACR3: 1 | ACS3: 1 | ACT3: 1 | ACU3: 1 | ACV3: 1 | ACW3: 0.9 | ACX3: 1.1 | ACY3: 0.9 | ACZ3: 1 | ADA3: 1 | ADB3: 1 | ADC3: 1 | ADD3: 1 | ADE3: 1.25 | ADF3: 1.1 | ADG3: 1 | ADH3: 1 | ADI3: 1 | ADJ3: 1 | ADK3: 1 | ADL3: 1 | ADM3: 1 | ADN3: 1.1 | ADO3: 1 | ADP3: 1 | ADQ3: 1.1 | ADR3: 1 | ADS3: 1 | ADT3: 1 | ADU3: 1 | ADV3: 0.9 | ADW3: 1 | ADX3: 1 | ADY3: 1.1 | ADZ3: 1 | AEA3: 1 | AEB3: 1 | AEC3: 1 | AED3: 1.25 | AEE3: 1 | AEG3: 1 | AEH3: 1 | AEI3: 1.1 | AEJ3: 0.9 | AEK3: 1 | AEL3: 1 | AEM3: 1.25 | AEN3: 1 | AEO3: 1 | AEP3: 1.1 | AEQ3: 1.1 | AER3: 1.25 | AES3: 1 | AET3: 1 | AEU3: 1 | AEV3: 0.9 | AEW3: 0.9 | AEX3: 1.25 | AEY3: 1 | AEZ3: 0.9 | AFA3: 1 | AFB3: 1.1 | AFC3: 1 | AFD3: 1.25 | AFE3: 1 | AFF3: 1 | AFG3: 1 | AFH3: 1 | AFI3: 1.1 | AFJ3: 1 | AFK3: 1 | AFL3: 1 | AFM3: 1 | AFN3: 0.9 | AFO3: 1 | AFP3: 1 | AFQ3: 1 | AFR3: 0.9 | AFS3: 1 | AFT3: 1 | AFU3: 1 | AFV3: 1 | AFW3: 1.1 | AFX3: 1.25 | AFY3: 1 | AFZ3: 0.9 | AGA3: 1 | AGB3: 1 | AGC3: 1 | AGD3: 1 | AGE3: 1 | AGF3: 0.9 | AGG3: 0.9 | AGH3: 1 | AGI3: 1 | AGJ3: 1.25 | AGK3: 1 | AGL3: 1.1 | AGM3: 1.1 | AGN3: 1 | AGO3: 1 | AGP3: 1 | AGQ3: 1 | AGR3: 0.9 | AGS3: 1.1
U4: Group 1 | V4: Group 1 | W4: Group 1 | X4: Group 1 | Y4: Group 1 | Z4: Group 1 | AA4: Group 1 | AB4: Forming | AC4: Forming | AD4: Forming | AE4: Forming | AF4: Forming | AG4: Forming | AH4: Forming | AI4: Forming | AJ4: Group 2 | AK4: Group 2 | AL4: Group 2 | AM4: Group 2 | AN4: Group 2 | AO4: Group 3 | AP4: Group 3 | AQ4: Group 3 | AR4: Group 3 | AS4: Group 3 | AT4: Group 3 | AU4: Group 3 | AV4: Group 3 | AW4: Group 3 | AX4: Group 3 | AY4: Group 4 | AZ4: Group 4 | BA4: Group 4 | BB4: Group 4 | BC4: Group 4 | BD4: Group 4 | BE4: Group 4 | BF4: Group 4 | BG4: Group 4 | BH4: Group 4 | BI4: Group 5 | BJ4: Group 5 | BK4: Group 5 | BL4: Group 5 | BM4: Group 5 | BN4: Group 5 | BO4: Group 5 | BP4: Group 5 | BQ4: Group 5 | BR4: Group 5 | BS4: Group 6 | BT4: Group 6 | BU4: Group 6 | BV4: Group 6 | BW4: Group 6 | BX4: Group 6 | BY4: Group 6 | BZ4: Group 6 | CA4: Group 6 | CB4: Group 6 | CC4: Group 7 | CD4: Group 7 | CE4: Group 7 | CF4: Group 7 | CG4: Group 7 | CH4: Plan | EV4: Plan | HJ4: Plan | JX4: Plan | ML4: Plan | OZ4: Plan | RN4: Plan | UB4: Plan | WP4: Plan | ZD4: Plan | ABR4: Plan | AEF4: Plan
F5: ASSY P/N | R5: FM | S5: BD | U5: Process 01 | V5: Process 02 | W5: Process 03 | X5: Process 04 | Y5: Process 05 | Z5: Process 06 | AA5: Process 07 | AB5: Reduce | AC5: Expand | AD5: Dimple | AE5: Stopper | AF5: Drill | AG5: Spin | AH5: Pinch Off | AI5: Press Joint | AJ5: Bending Pipe | AK5: Process 17 | AL5: Process 18 | AM5: Process 19 | AN5: Process 20 | AO5: Process 21 | AP5: Process 22 | AQ5: Process 23 | AR5: Process 24 | AS5: Process 25 | AT5: Process 26 | AU5: Process 27 | AV5: Process 28 | AW5: Process 29 | AX5: Process 30 | AY5: Process 31 | AZ5: Process 32 | BA5: Process 33 | BB5: Process 34 | BC5: Process 35 | BD5: Process 36 | BE5: Process 37 | BF5: Process 38 | BG5: Process 39 | BH5: Process 40 | BI5: Process 41 | BJ5: Process 42 | BK5: Process 43 | BL5: Process 44 | BM5: Process 45 | BN5: Process 46 | BO5: Process 47 | BP5: Process 48 | BQ5: Process 49 | BR5: Process 50 | BS5: Process 51 | BT5: Process 52 | BU5: Process 53 | BV5: Process 54 | BW5: Process 55 | BX5: Process 56 | BY5: Process 57 | BZ5: Process 58 | CA5: Process 59 | CB5: Process 60 | CC5: Process 61 | CD5: Process 62 | CE5: Process 63 | CF5: Process 64 | CG5: Process 65 | CH5: JAN | CI5: Process 01 | CJ5: Process 02 | CK5: Process 03 | CL5: Process 04 | CM5: Process 05 | CN5: Process 06 | CO5: Process 07 | CP5: Reduce | CQ5: Expand | CR5: Dimple | CS5: Stopper | CT5: Drill | CU5: Spin | CV5: Pinch Off | CW5: Press Joint | CX5: Bending Pipe | CY5: Process 17 | CZ5: Process 18 | DA5: Process 19 | DB5: Process 20 | DC5: Process 21 | DD5: Process 22 | DE5: Process 23 | DF5: Process 24 | DG5: Process 25 | DH5: Process 26 | DI5: Process 27 | DJ5: Process 28 | DK5: Process 29 | DL5: Process 30 | DM5: Process 31 | DN5: Process 32 | DO5: Process 33 | DP5: Process 34 | DQ5: Process 35 | DR5: Process 36 | DS5: Process 37 | DT5: Process 38 | DU5: Process 39 | DV5: Process 40 | DW5: Process 41 | DX5: Process 42 | DY5: Process 43 | DZ5: Process 44 | EA5: Process 45 | EB5: Process 46 | EC5: Process 47 | ED5: Process 48 | EE5: Process 49 | EF5: Process 50 | EG5: Process 51 | EH5: Process 52 | EI5: Process 53 | EJ5: Process 54 | EK5: Process 55 | EL5: Process 56 | EM5: Process 57 | EN5: Process 58 | EO5: Process 59 | EP5: Process 60 | EQ5: Process 61 | ER5: Process 62 | ES5: Process 63 | ET5: Process 64 | EU5: Process 65 | EV5: FEB | EW5: Process 01 | EX5: Process 02 | EY5: Process 03 | EZ5: Process 04 | FA5: Process 05 | FB5: Process 06 | FC5: Process 07 | FD5: Reduce | FE5: Expand | FF5: Dimple | FG5: Stopper | FH5: Drill | FI5: Spin | FJ5: Pinch Off | FK5: Press Joint | FL5: Bending Pipe | FM5: Process 17 | FN5: Process 18 | FO5: Process 19 | FP5: Process 20 | FQ5: Process 21 | FR5: Process 22 | FS5: Process 23 | FT5: Process 24 | FU5: Process 25 | FV5: Process 26 | FW5: Process 27 | FX5: Process 28 | FY5: Process 29 | FZ5: Process 30 | GA5: Process 31 | GB5: Process 32 | GC5: Process 33 | GD5: Process 34 | GE5: Process 35 | GF5: Process 36 | GG5: Process 37 | GH5: Process 38 | GI5: Process 39 | GJ5: Process 40 | GK5: Process 41 | GL5: Process 42 | GM5: Process 43 | GN5: Process 44 | GO5: Process 45 | GP5: Process 46 | GQ5: Process 47 | GR5: Process 48 | GS5: Process 49 | GT5: Process 50 | GU5: Process 51 | GV5: Process 52 | GW5: Process 53 | GX5: Process 54 | GY5: Process 55 | GZ5: Process 56 | HA5: Process 57 | HB5: Process 58 | HC5: Process 59 | HD5: Process 60 | HE5: Process 61 | HF5: Process 62 | HG5: Process 63 | HH5: Process 64 | HI5: Process 65 | HJ5: MAR | HK5: Process 01 | HL5: Process 02 | HM5: Process 03 | HN5: Process 04 | HO5: Process 05 | HP5: Process 06 | HQ5: Process 07 | HR5: Reduce | HS5: Expand | HT5: Dimple | HU5: Stopper | HV5: Drill | HW5: Spin | HX5: Pinch Off | HY5: Press Joint | HZ5: Bending Pipe | IA5: Process 17 | IB5: Process 18 | IC5: Process 19 | ID5: Process 20 | IE5: Process 21 | IF5: Process 22 | IG5: Process 23 | IH5: Process 24 | II5: Process 25 | IJ5: Process 26 | IK5: Process 27 | IL5: Process 28 | IM5: Process 29 | IN5: Process 30 | IO5: Process 31 | IP5: Process 32 | IQ5: Process 33 | IR5: Process 34 | IS5: Process 35 | IT5: Process 36 | IU5: Process 37 | IV5: Process 38 | IW5: Process 39 | IX5: Process 40 | IY5: Process 41 | IZ5: Process 42 | JA5: Process 43 | JB5: Process 44 | JC5: Process 45 | JD5: Process 46 | JE5: Process 47 | JF5: Process 48 | JG5: Process 49 | JH5: Process 50 | JI5: Process 51 | JJ5: Process 52 | JK5: Process 53 | JL5: Process 54 | JM5: Process 55 | JN5: Process 56 | JO5: Process 57 | JP5: Process 58 | JQ5: Process 59 | JR5: Process 60 | JS5: Process 61 | JT5: Process 62 | JU5: Process 63 | JV5: Process 64 | JW5: Process 65 | JX5: APR | JY5: Process 01 | JZ5: Process 02 | KA5: Process 03 | KB5: Process 04 | KC5: Process 05 | KD5: Process 06 | KE5: Process 07 | KF5: Reduce | KG5: Expand | KH5: Dimple | KI5: Stopper | KJ5: Drill | KK5: Spin | KL5: Pinch Off | KM5: Press Joint | KN5: Bending Pipe | KO5: Process 17 | KP5: Process 18 | KQ5: Process 19 | KR5: Process 20 | KS5: Process 21 | KT5: Process 22 | KU5: Process 23 | KV5: Process 24 | KW5: Process 25 | KX5: Process 26 | KY5: Process 27 | KZ5: Process 28 | LA5: Process 29 | LB5: Process 30 | LC5: Process 31 | LD5: Process 32 | LE5: Process 33 | LF5: Process 34 | LG5: Process 35 | LH5: Process 36 | LI5: Process 37 | LJ5: Process 38 | LK5: Process 39 | LL5: Process 40 | LM5: Process 41 | LN5: Process 42 | LO5: Process 43 | LP5: Process 44 | LQ5: Process 45 | LR5: Process 46 | LS5: Process 47 | LT5: Process 48 | LU5: Process 49 | LV5: Process 50 | LW5: Process 51 | LX5: Process 52 | LY5: Process 53 | LZ5: Process 54 | MA5: Process 55 | MB5: Process 56 | MC5: Process 57 | MD5: Process 58 | ME5: Process 59 | MF5: Process 60 | MG5: Process 61 | MH5: Process 62 | MI5: Process 63 | MJ5: Process 64 | MK5: Process 65 | ML5: MAY | MM5: Process 01 | MN5: Process 02 | MO5: Process 03 | MP5: Process 04 | MQ5: Process 05 | MR5: Process 06 | MS5: Process 07 | MT5: Reduce | MU5: Expand | MV5: Dimple | MW5: Stopper | MX5: Drill | MY5: Spin | MZ5: Pinch Off | NA5: Press Joint | NB5: Bending Pipe | NC5: Process 17 | ND5: Process 18 | NE5: Process 19 | NF5: Process 20 | NG5: Process 21 | NH5: Process 22 | NI5: Process 23 | NJ5: Process 24 | NK5: Process 25 | NL5: Process 26 | NM5: Process 27 | NN5: Process 28 | NO5: Process 29 | NP5: Process 30 | NQ5: Process 31 | NR5: Process 32 | NS5: Process 33 | NT5: Process 34 | NU5: Process 35 | NV5: Process 36 | NW5: Process 37 | NX5: Process 38 | NY5: Process 39 | NZ5: Process 40 | OA5: Process 41 | OB5: Process 42 | OC5: Process 43 | OD5: Process 44 | OE5: Process 45 | OF5: Process 46 | OG5: Process 47 | OH5: Process 48 | OI5: Process 49 | OJ5: Process 50 | OK5: Process 51 | OL5: Process 52 | OM5: Process 53 | ON5: Process 54 | OO5: Process 55 | OP5: Process 56 | OQ5: Process 57 | OR5: Process 58 | OS5: Process 59 | OT5: Process 60 | OU5: Process 61 | OV5: Process 62 | OW5: Process 63 | OX5: Process 64 | OY5: Process 65 | OZ5: JUN | PA5: Process 01 | PB5: Process 02 | PC5: Process 03 | PD5: Process 04 | PE5: Process 05 | PF5: Process 06 | PG5: Process 07 | PH5: Reduce | PI5: Expand | PJ5: Dimple | PK5: Stopper | PL5: Drill | PM5: Spin | PN5: Pinch Off | PO5: Press Joint | PP5: Bending Pipe | PQ5: Process 17 | PR5: Process 18 | PS5: Process 19 | PT5: Process 20 | PU5: Process 21 | PV5: Process 22 | PW5: Process 23 | PX5: Process 24 | PY5: Process 25 | PZ5: Process 26 | QA5: Process 27 | QB5: Process 28 | QC5: Process 29 | QD5: Process 30 | QE5: Process 31 | QF5: Process 32 | QG5: Process 33 | QH5: Process 34 | QI5: Process 35 | QJ5: Process 36 | QK5: Process 37 | QL5: Process 38 | QM5: Process 39 | QN5: Process 40 | QO5: Process 41 | QP5: Process 42 | QQ5: Process 43 | QR5: Process 44 | QS5: Process 45 | QT5: Process 46 | QU5: Process 47 | QV5: Process 48 | QW5: Process 49 | QX5: Process 50 | QY5: Process 51 | QZ5: Process 52 | RA5: Process 53 | RB5: Process 54 | RC5: Process 55 | RD5: Process 56 | RE5: Process 57 | RF5: Process 58 | RG5: Process 59 | RH5: Process 60 | RI5: Process 61 | RJ5: Process 62 | RK5: Process 63 | RL5: Process 64 | RM5: Process 65 | RN5: JUL | RO5: Process 01 | RP5: Process 02 | RQ5: Process 03 | RR5: Process 04 | RS5: Process 05 | RT5: Process 06 | RU5: Process 07 | RV5: Reduce | RW5: Expand | RX5: Dimple | RY5: Stopper | RZ5: Drill | SA5: Spin | SB5: Pinch Off | SC5: Press Joint | SD5: Bending Pipe | SE5: Process 17 | SF5: Process 18 | SG5: Process 19 | SH5: Process 20 | SI5: Process 21 | SJ5: Process 22 | SK5: Process 23 | SL5: Process 24 | SM5: Process 25 | SN5: Process 26 | SO5: Process 27 | SP5: Process 28 | SQ5: Process 29 | SR5: Process 30 | SS5: Process 31 | ST5: Process 32 | SU5: Process 33 | SV5: Process 34 | SW5: Process 35 | SX5: Process 36 | SY5: Process 37 | SZ5: Process 38 | TA5: Process 39 | TB5: Process 40 | TC5: Process 41 | TD5: Process 42 | TE5: Process 43 | TF5: Process 44 | TG5: Process 45 | TH5: Process 46 | TI5: Process 47 | TJ5: Process 48 | TK5: Process 49 | TL5: Process 50 | TM5: Process 51 | TN5: Process 52 | TO5: Process 53 | TP5: Process 54 | TQ5: Process 55 | TR5: Process 56 | TS5: Process 57 | TT5: Process 58 | TU5: Process 59 | TV5: Process 60 | TW5: Process 61 | TX5: Process 62 | TY5: Process 63 | TZ5: Process 64 | UA5: Process 65 | UB5: AUG | UC5: Process 01 | UD5: Process 02 | UE5: Process 03 | UF5: Process 04 | UG5: Process 05 | UH5: Process 06 | UI5: Process 07 | UJ5: Reduce | UK5: Expand | UL5: Dimple | UM5: Stopper | UN5: Drill | UO5: Spin | UP5: Pinch Off | UQ5: Press Joint | UR5: Bending Pipe | US5: Process 17 | UT5: Process 18 | UU5: Process 19 | UV5: Process 20 | UW5: Process 21 | UX5: Process 22 | UY5: Process 23 | UZ5: Process 24 | VA5: Process 25 | VB5: Process 26 | VC5: Process 27 | VD5: Process 28 | VE5: Process 29 | VF5: Process 30 | VG5: Process 31 | VH5: Process 32 | VI5: Process 33 | VJ5: Process 34 | VK5: Process 35 | VL5: Process 36 | VM5: Process 37 | VN5: Process 38 | VO5: Process 39 | VP5: Process 40 | VQ5: Process 41 | VR5: Process 42 | VS5: Process 43 | VT5: Process 44 | VU5: Process 45 | VV5: Process 46 | VW5: Process 47 | VX5: Process 48 | VY5: Process 49 | VZ5: Process 50 | WA5: Process 51 | WB5: Process 52 | WC5: Process 53 | WD5: Process 54 | WE5: Process 55 | WF5: Process 56 | WG5: Process 57 | WH5: Process 58 | WI5: Process 59 | WJ5: Process 60 | WK5: Process 61 | WL5: Process 62 | WM5: Process 63 | WN5: Process 64 | WO5: Process 65 | WP5: SEP | WQ5: Process 01 | WR5: Process 02 | WS5: Process 03 | WT5: Process 04 | WU5: Process 05 | WV5: Process 06 | WW5: Process 07 | WX5: Reduce | WY5: Expand | WZ5: Dimple | XA5: Stopper | XB5: Drill | XC5: Spin | XD5: Pinch Off | XE5: Press Joint | XF5: Bending Pipe | XG5: Process 17 | XH5: Process 18 | XI5: Process 19 | XJ5: Process 20 | XK5: Process 21 | XL5: Process 22 | XM5: Process 23 | XN5: Process 24 | XO5: Process 25 | XP5: Process 26 | XQ5: Process 27 | XR5: Process 28 | XS5: Process 29 | XT5: Process 30 | XU5: Process 31 | XV5: Process 32 | XW5: Process 33 | XX5: Process 34 | XY5: Process 35 | XZ5: Process 36 | YA5: Process 37 | YB5: Process 38 | YC5: Process 39 | YD5: Process 40 | YE5: Process 41 | YF5: Process 42 | YG5: Process 43 | YH5: Process 44 | YI5: Process 45 | YJ5: Process 46 | YK5: Process 47 | YL5: Process 48 | YM5: Process 49 | YN5: Process 50 | YO5: Process 51 | YP5: Process 52 | YQ5: Process 53 | YR5: Process 54 | YS5: Process 55 | YT5: Process 56 | YU5: Process 57 | YV5: Process 58 | YW5: Process 59 | YX5: Process 60 | YY5: Process 61 | YZ5: Process 62 | ZA5: Process 63 | ZB5: Process 64 | ZC5: Process 65 | ZD5: OCT | ZE5: Process 01 | ZF5: Process 02 | ZG5: Process 03 | ZH5: Process 04 | ZI5: Process 05 | ZJ5: Process 06 | ZK5: Process 07 | ZL5: Reduce | ZM5: Expand | ZN5: Dimple | ZO5: Stopper | ZP5: Drill | ZQ5: Spin | ZR5: Pinch Off | ZS5: Press Joint | ZT5: Bending Pipe | ZU5: Process 17 | ZV5: Process 18 | ZW5: Process 19 | ZX5: Process 20 | ZY5: Process 21 | ZZ5: Process 22 | AAA5: Process 23 | AAB5: Process 24 | AAC5: Process 25 | AAD5: Process 26 | AAE5: Process 27 | AAF5: Process 28 | AAG5: Process 29 | AAH5: Process 30 | AAI5: Process 31 | AAJ5: Process 32 | AAK5: Process 33 | AAL5: Process 34 | AAM5: Process 35 | AAN5: Process 36 | AAO5: Process 37 | AAP5: Process 38 | AAQ5: Process 39 | AAR5: Process 40 | AAS5: Process 41 | AAT5: Process 42 | AAU5: Process 43 | AAV5: Process 44 | AAW5: Process 45 | AAX5: Process 46 | AAY5: Process 47 | AAZ5: Process 48 | ABA5: Process 49 | ABB5: Process 50 | ABC5: Process 51 | ABD5: Process 52 | ABE5: Process 53 | ABF5: Process 54 | ABG5: Process 55 | ABH5: Process 56 | ABI5: Process 57 | ABJ5: Process 58 | ABK5: Process 59 | ABL5: Process 60 | ABM5: Process 61 | ABN5: Process 62 | ABO5: Process 63 | ABP5: Process 64 | ABQ5: Process 65 | ABR5: NOV | ABS5: Process 01 | ABT5: Process 02 | ABU5: Process 03 | ABV5: Process 04 | ABW5: Process 05 | ABX5: Process 06 | ABY5: Process 07 | ABZ5: Reduce | ACA5: Expand | ACB5: Dimple | ACC5: Stopper | ACD5: Drill | ACE5: Spin | ACF5: Pinch Off | ACG5: Press Joint | ACH5: Bending Pipe | ACI5: Process 17 | ACJ5: Process 18 | ACK5: Process 19 | ACL5: Process 20 | ACM5: Process 21 | ACN5: Process 22 | ACO5: Process 23 | ACP5: Process 24 | ACQ5: Process 25 | ACR5: Process 26 | ACS5: Process 27 | ACT5: Process 28 | ACU5: Process 29 | ACV5: Process 30 | ACW5: Process 31 | ACX5: Process 32 | ACY5: Process 33 | ACZ5: Process 34 | ADA5: Process 35 | ADB5: Process 36 | ADC5: Process 37 | ADD5: Process 38 | ADE5: Process 39 | ADF5: Process 40 | ADG5: Process 41 | ADH5: Process 42 | ADI5: Process 43 | ADJ5: Process 44 | ADK5: Process 45 | ADL5: Process 46 | ADM5: Process 47 | ADN5: Process 48 | ADO5: Process 49 | ADP5: Process 50 | ADQ5: Process 51 | ADR5: Process 52 | ADS5: Process 53 | ADT5: Process 54 | ADU5: Process 55 | ADV5: Process 56 | ADW5: Process 57 | ADX5: Process 58 | ADY5: Process 59 | ADZ5: Process 60 | AEA5: Process 61 | AEB5: Process 62 | AEC5: Process 63 | AED5: Process 64 | AEE5: Process 65 | AEF5: DEC | AEG5: Process 01 | AEH5: Process 02 | AEI5: Process 03 | AEJ5: Process 04 | AEK5: Process 05 | AEL5: Process 06 | AEM5: Process 07 | AEN5: Reduce | AEO5: Expand | AEP5: Dimple | AEQ5: Stopper | AER5: Drill | AES5: Spin | AET5: Pinch Off | AEU5: Press Joint | AEV5: Bending Pipe | AEW5: Process 17 | AEX5: Process 18 | AEY5: Process 19 | AEZ5: Process 20 | AFA5: Process 21 | AFB5: Process 22 | AFC5: Process 23 | AFD5: Process 24 | AFE5: Process 25 | AFF5: Process 26 | AFG5: Process 27 | AFH5: Process 28 | AFI5: Process 29 | AFJ5: Process 30 | AFK5: Process 31 | AFL5: Process 32 | AFM5: Process 33 | AFN5: Process 34 | AFO5: Process 35 | AFP5: Process 36 | AFQ5: Process 37 | AFR5: Process 38 | AFS5: Process 39 | AFT5: Process 40 | AFU5: Process 41 | AFV5: Process 42 | AFW5: Process 43 | AFX5: Process 44 | AFY5: Process 45 | AFZ5: Process 46 | AGA5: Process 47 | AGB5: Process 48 | AGC5: Process 49 | AGD5: Process 50 | AGE5: Process 51 | AGF5: Process 52 | AGG5: Process 53 | AGH5: Process 54 | AGI5: Process 55 | AGJ5: Process 56 | AGK5: Process 57 | AGL5: Process 58 | AGM5: Process 59 | AGN5: Process 60 | AGO5: Process 61 | AGP5: Process 62 | AGQ5: Process 63 | AGR5: Process 64 | AGS5: Process 65 | AGU5: Q'TY JAN | AGV5: Q'TY FEB | AGW5: Q'TY MAR | AGX5: Q'TY APR | AGY5: Q'TY MAY | AGZ5: Q'TY JUN | AHA5: Q'TY JUL | AHB5: Q'TY AUG | AHC5: Q'TY SEP | AHD5: Q'TY OCT | AHE5: Q'TY NOV | AHF5: Q'TY DEC
F7: ASSY-999 | H7: CH-000 | I7: part 0 | K7: 1 | L7: 6.35 | P7: 1 | R7: 0 | S7: 0 | AB7: 2.1 | AC7: 48.15 | AD7: 43.79 | AE7: 33.77 | AF7: 15.66 | AG7: 33 | AH7: 5 | AJ7: 27.69 | AQ7: 56.65 | AS7: 27.08 | AT7: 5.31 | AX7: 24 | AY7: 30 | AZ7: 26 | BB7: 14.2 | BH7: 20.94 | BM7: 8 | BQ7: 3.34 | BS7: 25.91 | BV7: 55.23 | BY7: 41.6 | CA7: 6 | CC7: 5 | CD7: 1.68 | CH7: 0 | CI7: 0 | CJ7: 0 | CK7: 0 | CL7: 0 | CM7: 0 | CN7: 0 | CO7: 0 | CP7: 0 | CQ7: 0 | CR7: 0 | CS7: 0 | CT7: 0 | CU7: 0 | CV7: 0 | CW7: 0 | CX7: 0 | CY7: 0 | CZ7: 0 | DA7: 0 | DB7: 0 | DC7: 0 | DD7: 0 | DE7: 0 | DF7: 0 | DG7: 0 | DH7: 0 | DI7: 0 | DJ7: 0 | DK7: 0 | DL7: 0 | DM7: 0 | DN7: 0 | DO7: 0 | DP7: 0 | DQ7: 0 | DR7: 0 | DS7: 0 | DT7: 0 | DU7: 0 | DV7: 0 | DW7: 0 | DX7: 0 | DY7: 0 | DZ7: 0 | EA7: 0 | EB7: 0 | EC7: 0 | ED7: 0 | EE7: 0 | EF7: 0 | EG7: 0 | EH7: 0 | EI7: 0 | EJ7: 0 | EK7: 0 | EL7: 0 | EM7: 0 | EN7: 0 | EO7: 0 | EP7: 0 | EQ7: 0 | ER7: 0 | ES7: 0 | ET7: 0 | EU7: 0 | EV7: 0 | EW7: 0 | EX7: 0 | EY7: 0 | EZ7: 0 | FA7: 0 | FB7: 0 | FC7: 0 | FD7: 0 | FE7: 0 | FF7: 0 | FG7: 0 | FH7: 0 | FI7: 0 | FJ7: 0 | FK7: 0 | FL7: 0 | FM7: 0 | FN7: 0 | FO7: 0 | FP7: 0 | FQ7: 0 | FR7: 0 | FS7: 0 | FT7: 0 | FU7: 0 | FV7: 0 | FW7: 0 | FX7: 0 | FY7: 0 | FZ7: 0 | GA7: 0 | GB7: 0 | GC7: 0 | GD7: 0 | GE7: 0 | GF7: 0 | GG7: 0 | GH7: 0 | GI7: 0 | GJ7: 0 | GK7: 0 | GL7: 0 | GM7: 0 | GN7: 0 | GO7: 0 | GP7: 0 | GQ7: 0 | GR7: 0 | GS7: 0 | GT7: 0 | GU7: 0 | GV7: 0 | GW7: 0 | GX7: 0 | GY7: 0 | GZ7: 0 | HA7: 0 | HB7: 0 | HC7: 0 | HD7: 0 | HE7: 0 | HF7: 0 | HG7: 0 | HH7: 0 | HI7: 0 | HJ7: 0 | HK7: 0 | HL7: 0 | HM7: 0 | HN7: 0 | HO7: 0 | HP7: 0 | HQ7: 0 | HR7: 0 | HS7: 0 | HT7: 0 | HU7: 0 | HV7: 0 | HW7: 0 | HX7: 0 | HY7: 0 | HZ7: 0 | IA7: 0 | IB7: 0 | IC7: 0 | ID7: 0 | IE7: 0 | IF7: 0 | IG7: 0 | IH7: 0 | II7: 0 | IJ7: 0 | IK7: 0 | IL7: 0 | IM7: 0 | IN7: 0 | IO7: 0 | IP7: 0 | IQ7: 0 | IR7: 0 | IS7: 0 | IT7: 0 | IU7: 0 | IV7: 0 | IW7: 0 | IX7: 0 | IY7: 0 | IZ7: 0 | JA7: 0 | JB7: 0 | JC7: 0 | JD7: 0 | JE7: 0 | JF7: 0 | JG7: 0 | JH7: 0 | JI7: 0 | JJ7: 0 | JK7: 0 | JL7: 0 | JM7: 0 | JN7: 0 | JO7: 0 | JP7: 0 | JQ7: 0 | JR7: 0 | JS7: 0 | JT7: 0 | JU7: 0 | JV7: 0 | JW7: 0 | JX7: 0 | JY7: 0 | JZ7: 0 | KA7: 0 | KB7: 0 | KC7: 0 | KD7: 0 | KE7: 0 | KF7: 0 | KG7: 0 | KH7: 0 | KI7: 0 | KJ7: 0 | KK7: 0 | KL7: 0 | KM7: 0 | KN7: 0 | KO7: 0 | KP7: 0 | KQ7: 0 | KR7: 0 | KS7: 0 | KT7: 0 | KU7: 0 | KV7: 0 | KW7: 0 | KX7: 0 | KY7: 0 | KZ7: 0 | LA7: 0 | LB7: 0 | LC7: 0 | LD7: 0 | LE7: 0 | LF7: 0 | LG7: 0 | LH7: 0 | LI7: 0 | LJ7: 0 | LK7: 0 | LL7: 0 | LM7: 0 | LN7: 0 | LO7: 0 | LP7: 0 | LQ7: 0 | LR7: 0 | LS7: 0 | LT7: 0 | LU7: 0 | LV7: 0 | LW7: 0 | LX7: 0 | LY7: 0 | LZ7: 0 | MA7: 0 | MB7: 0 | MC7: 0 | MD7: 0 | ME7: 0 | MF7: 0 | MG7: 0 | MH7: 0 | MI7: 0 | MJ7: 0 | MK7: 0 | ML7: 0 | MM7: 0 | MN7: 0 | MO7: 0 | MP7: 0 | MQ7: 0 | MR7: 0 | MS7: 0 | MT7: 0 | MU7: 0 | MV7: 0 | MW7: 0 | MX7: 0 | MY7: 0 | MZ7: 0 | NA7: 0 | NB7: 0 | NC7: 0 | ND7: 0 | NE7: 0 | NF7: 0 | NG7: 0 | NH7: 0 | NI7: 0 | NJ7: 0 | NK7: 0 | NL7: 0 | NM7: 0 | NN7: 0 | NO7: 0 | NP7: 0 | NQ7: 0 | NR7: 0 | NS7: 0 | NT7: 0 | NU7: 0 | NV7: 0 | NW7: 0 | NX7: 0 | NY7: 0 | NZ7: 0 | OA7: 0 | OB7: 0 | OC7: 0 | OD7: 0 | OE7: 0 | OF7: 0 | OG7: 0 | OH7: 0 | OI7: 0 | OJ7: 0 | OK7: 0 | OL7: 0 | OM7: 0 | ON7: 0 | OO7: 0 | OP7: 0 | OQ7: 0 | OR7: 0 | OS7: 0 | OT7: 0 | OU7: 0 | OV7: 0 | OW7: 0 | OX7: 0 | OY7: 0 | OZ7: 0 | PA7: 0 | PB7: 0 | PC7: 0 | PD7: 0 | PE7: 0 | PF7: 0 | PG7: 0 | PH7: 0 | PI7: 0 | PJ7: 0 | PK7: 0 | PL7: 0 | PM7: 0 | PN7: 0 | PO7: 0 | PP7: 0 | PQ7: 0 | PR7: 0 | PS7: 0 | PT7: 0 | PU7: 0 | PV7: 0 | PW7: 0 | PX7: 0 | PY7: 0 | PZ7: 0 | QA7: 0 | QB7: 0 | QC7: 0 | QD7: 0 | QE7: 0 | QF7: 0 | QG7: 0 | QH7: 0 | QI7: 0 | QJ7: 0 | QK7: 0 | QL7: 0 | QM7: 0 | QN7: 0 | QO7: 0 | QP7: 0 | QQ7: 0 | QR7: 0 | QS7: 0 | QT7: 0 | QU7: 0 | QV7: 0 | QW7: 0 | QX7: 0 | QY7: 0 | QZ7: 0 | RA7: 0 | RB7: 0 | RC7: 0 | RD7: 0 | RE7: 0 | RF7: 0 | RG7: 0 | RH7: 0 | RI7: 0 | RJ7: 0 | RK7: 0 | RL7: 0 | RM7: 0 | RN7: 0 | RO7: 0 | RP7: 0 | RQ7: 0 | RR7: 0 | RS7: 0 | RT7: 0 | RU7: 0 | RV7: 0 | RW7: 0 | RX7: 0 | RY7: 0 | RZ7: 0 | SA7: 0 | SB7: 0 | SC7: 0 | SD7: 0 | SE7: 0 | SF7: 0 | SG7: 0 | SH7: 0 | SI7: 0 | SJ7: 0 | SK7: 0 | SL7: 0 | SM7: 0 | SN7: 0 | SO7: 0 | SP7: 0 | SQ7: 0 | SR7: 0 | SS7: 0 | ST7: 0 | SU7: 0 | SV7: 0 | SW7: 0 | SX7: 0 | SY7: 0 | SZ7: 0 | TA7: 0 | TB7: 0 | TC7: 0 | TD7: 0 | TE7: 0 | TF7: 0 | TG7: 0 | TH7: 0 | TI7: 0 | TJ7: 0 | TK7: 0 | TL7: 0 | TM7: 0 | TN7: 0 | TO7: 0 | TP7: 0 | TQ7: 0 | TR7: 0 | TS7: 0 | TT7: 0 | TU7: 0 | TV7: 0 | TW7: 0 | TX7: 0 | TY7: 0 | TZ7: 0 | UA7: 0 | UB7: 0 | UC7: 0 | UD7: 0 | UE7: 0 | UF7: 0 | UG7: 0 | UH7: 0 | UI7: 0 | UJ7: 0 | UK7: 0 | UL7: 0 | UM7: 0 | UN7: 0 | UO7: 0 | UP7: 0 | UQ7: 0 | UR7: 0 | US7: 0 | UT7: 0 | UU7: 0 | UV7: 0 | UW7: 0 | UX7: 0 | UY7: 0 | UZ7: 0 | VA7: 0 | VB7: 0 | VC7: 0 | VD7: 0 | VE7: 0 | VF7: 0 | VG7: 0 | VH7: 0 | VI7: 0 | VJ7: 0 | VK7: 0 | VL7: 0 | VM7: 0 | VN7: 0 | VO7: 0 | VP7: 0 | VQ7: 0 | VR7: 0 | VS7: 0 | VT7: 0 | VU7: 0 | VV7: 0 | VW7: 0 | VX7: 0 | VY7: 0 | VZ7: 0 | WA7: 0 | WB7: 0 | WC7: 0 | WD7: 0 | WE7: 0 | WF7: 0 | WG7: 0 | WH7: 0 | WI7: 0 | WJ7: 0 | WK7: 0 | WL7: 0 | WM7: 0 | WN7: 0 | WO7: 0 | WP7: 0 | WQ7: 0 | WR7: 0 | WS7: 0 | WT7: 0 | WU7: 0 | WV7: 0 | WW7: 0 | WX7: 0 | WY7: 0 | WZ7: 0 | XA7: 0 | XB7: 0 | XC7: 0 | XD7: 0 | XE7: 0 | XF7: 0 | XG7: 0 | XH7: 0 | XI7: 0 | XJ7: 0 | XK7: 0 | XL7: 0 | XM7: 0 | XN7: 0 | XO7: 0 | XP7: 0 | XQ7: 0 | XR7: 0 | XS7: 0 | XT7: 0 | XU7: 0 | XV7: 0 | XW7: 0 | XX7: 0 | XY7: 0 | XZ7: 0 | YA7: 0 | YB7: 0 | YC7: 0 | YD7: 0 | YE7: 0 | YF7: 0 | YG7: 0 | YH7: 0 | YI7: 0 | YJ7: 0 | YK7: 0 | YL7: 0 | YM7: 0 | YN7: 0 | YO7: 0 | YP7: 0 | YQ7: 0 | YR7: 0 | YS7: 0 | YT7: 0 | YU7: 0 | YV7: 0 | YW7: 0 | YX7: 0 | YY7: 0 | YZ7: 0 | ZA7: 0 | ZB7: 0 | ZC7: 0 | ZD7: 0 | ZE7: 0 | ZF7: 0 | ZG7: 0 | ZH7: 0 | ZI7: 0 | ZJ7: 0 | ZK7: 0 | ZL7: 0 | ZM7: 0 | ZN7: 0 | ZO7: 0 | ZP7: 0 | ZQ7: 0 | ZR7: 0 | ZS7: 0 | ZT7: 0 | ZU7: 0 | ZV7: 0 | ZW7: 0 | ZX7: 0 | ZY7: 0 | ZZ7: 0 | AAA7: 0 | AAB7: 0 | AAC7: 0 | AAD7: 0 | AAE7: 0 | AAF7: 0 | AAG7: 0 | AAH7: 0 | AAI7: 0 | AAJ7: 0 | AAK7: 0 | AAL7: 0 | AAM7: 0 | AAN7: 0 | AAO7: 0 | AAP7: 0 | AAQ7: 0 | AAR7: 0 | AAS7: 0 | AAT7: 0 | AAU7: 0 | AAV7: 0 | AAW7: 0 | AAX7: 0 | AAY7: 0 | AAZ7: 0 | ABA7: 0 | ABB7: 0 | ABC7: 0 | ABD7: 0 | ABE7: 0 | ABF7: 0 | ABG7: 0 | ABH7: 0 | ABI7: 0 | ABJ7: 0 | ABK7: 0 | ABL7: 0 | ABM7: 0 | ABN7: 0 | ABO7: 0 | ABP7: 0 | ABQ7: 0 | ABR7: 0 | ABS7: 0 | ABT7: 0 | ABU7: 0 | ABV7: 0 | ABW7: 0 | ABX7: 0 | ABY7: 0 | ABZ7: 0 | ACA7: 0 | ACB7: 0 | ACC7: 0 | ACD7: 0 | ACE7: 0 | ACF7: 0 | ACG7: 0 | ACH7: 0 | ACI7: 0 | ACJ7: 0 | ACK7: 0 | ACL7: 0 | ACM7: 0 | ACN7: 0 | ACO7: 0 | ACP7: 0 | ACQ7: 0 | ACR7: 0 | ACS7: 0 | ACT7: 0 | ACU7: 0 | ACV7: 0 | ACW7: 0 | ACX7: 0 | ACY7: 0 | ACZ7: 0 | ADA7: 0 | ADB7: 0 | ADC7: 0 | ADD7: 0 | ADE7: 0 | ADF7: 0 | ADG7: 0 | ADH7: 0 | ADI7: 0 | ADJ7: 0 | ADK7: 0 | ADL7: 0 | ADM7: 0 | ADN7: 0 | ADO7: 0 | ADP7: 0 | ADQ7: 0 | ADR7: 0 | ADS7: 0 | ADT7: 0 | ADU7: 0 | ADV7: 0 | ADW7: 0 | ADX7: 0 | ADY7: 0 | ADZ7: 0 | AEA7: 0 | AEB7: 0 | AEC7: 0 | AED7: 0 | AEE7: 0 | AEF7: 0 | AEG7: 0 | AEH7: 0 | AEI7: 0 | AEJ7: 0 | AEK7: 0 | AEL7: 0 | AEM7: 0 | AEN7: 0 | AEO7: 0 | AEP7: 0 | AEQ7: 0 | AER7: 0 | AES7: 0 | AET7: 0 | AEU7: 0 | AEV7: 0 | AEW7: 0 | AEX7: 0 | AEY7: 0 | AEZ7: 0 | AFA7: 0 | AFB7: 0 | AFC7: 0 | AFD7: 0 | AFE7: 0 | AFF7: 0 | AFG7: 0 | AFH7: 0 | AFI7: 0 | AFJ7: 0 | AFK7: 0 | AFL7: 0 | AFM7: 0 | AFN7: 0 | AFO7: 0 | AFP7: 0 | AFQ7: 0 | AFR7: 0 | AFS7: 0 | AFT7: 0 | AFU7: 0 | AFV7: 0 | AFW7: 0 | AFX7: 0 | AFY7: 0 | AFZ7: 0 | AGA7: 0 | AGB7: 0 | AGC7: 0 | AGD7: 0 | AGE7: 0 | AGF7: 0 | AGG7: 0 | AGH7: 0 | AGI7: 0 | AGJ7: 0 | AGK7: 0 | AGL7: 0 | AGM7: 0 | AGN7: 0 | AGO7: 0 | AGP7: 0 | AGQ7: 0 | AGR7: 0 | AGS7: 0 | AGU7: =IF($P7>0,CH7*$K7,0) -> 0 | AGV7: =IF($P7>0,EV7*$K7,0) -> 0 | AGW7: =IF($P7>0,HJ7*$K7,0) -> 0 | AGX7: =IF($P7>0,JX7*$K7,0) -> 0 | AGY7: =IF($P7>0,ML7*$K7,0) -> 0 | AGZ7: =IF($P7>0,OZ7*$K7,0) -> 0 | AHA7: =IF($P7>0,RN7*$K7,0) -> 0 | AHB7: =IF($P7>0,UB7*$K7,0) -> 0 | AHC7: =IF($P7>0,WP7*$K7,0) -> 0 | AHD7: =IF($P7>0,ZD7*$K7,0) -> 0 | AHE7: =IF($P7>0,ABR7*$K7,0) -> 0 | AHF7: =IF($P7>0,AEF7*$K7,0) -> 0
F8: ASSY-020 | H8: CH-001 | I8: part 1 | K8: 1 | L8: 9.52 | P8: 1 | R8: FMCNC1 | S8: BD | V8: 10.53 | W8: 19.41 | X8: 19 | AA8: 17 | AB8: 30.83 | AC8: 27.38 | AE8: 33 | AF8: 14.54 | AG8: 9 | AH8: 8.66 | AI8: 17 | AJ8: 23.47 | AO8: 16.87 | AP8: 20.41 | AR8: 53.06 | AS8: 20.78 | AT8: 39.71 | AU8: 6 | AV8: 24.57 | AW8: 18.95 | AX8: 32.22 | BD8: 10 | BE8: 9.54 | BP8: 48.08 | BT8: 38.59 | BX8: 32.36 | BY8: 27.96 | BZ8: 35 | CA8: 45 | CE8: 15 | CH8: 192 | CI8: 0 | CJ8: 2021.76 | CK8: 3726.72 | CL8: 3648 | CM8: 0 | CN8: 0 | CO8: 4080 | CP8: 41435.52 | CQ8: 36798.72 | CR8: 0 | CS8: 44352 | CT8: 19541.76 | CU8: 12096 | CV8: 11639.04 | CW8: 22848 | CX8: 4506.24 | CY8: 0 | CZ8: 0 | DA8: 0 | DB8: 0 | DC8: 3239.04 | DD8: 3918.72 | DE8: 0 | DF8: 10187.52 | DG8: 3989.76 | DH8: 7624.32 | DI8: 1152 | DJ8: 5896.8 | DK8: 3638.4 | DL8: 6804.864 | DM8: 0 | DN8: 0 | DO8: 0 | DP8: 0 | DQ8: 0 | DR8: 1920 | DS8: 1831.68 | DT8: 0 | DU8: 0 | DV8: 0 | DW8: 0 | DX8: 0 | DY8: 0 | DZ8: 0 | EA8: 0 | EB8: 0 | EC8: 0 | ED8: 11539.2 | EE8: 0 | EF8: 0 | EG8: 0 | EH8: 9261.6 | EI8: 0 | EJ8: 0 | EK8: 0 | EL8: 6213.12 | EM8: 5368.32 | EN8: 6720 | EO8: 8640 | EP8: 0 | EQ8: 0 | ER8: 0 | ES8: 2880 | ET8: 0 | EU8: 0 | EV8: 76 | EW8: 0 | EX8: 800.28 | EY8: 1475.16 | EZ8: 1444 | FA8: 0 | FB8: 0 | FC8: 1292 | FD8: 16401.56 | FE8: 14566.16 | FF8: 0 | FG8: 17556 | FH8: 7735.28 | FI8: 4788 | FJ8: 4607.12 | FK8: 9044 | FL8: 1783.72 | FM8: 0 | FN8: 0 | FO8: 0 | FP8: 0 | FQ8: 1282.12 | FR8: 1551.16 | FS8: 0 | FT8: 4032.56 | FU8: 1421.352 | FV8: 3017.96 | FW8: 456 | FX8: 1680.588 | FY8: 1800.25 | FZ8: 2693.592 | GA8: 0 | GB8: 0 | GC8: 0 | GD8: 0 | GE8: 0 | GF8: 760 | GG8: 725.04 | GH8: 0 | GI8: 0 | GJ8: 0 | GK8: 0 | GL8: 0 | GM8: 0 | GN8: 0 | GO8: 0 | GP8: 0 | GQ8: 0 | GR8: 3654.08 | GS8: 0 | GT8: 0 | GU8: 0 | GV8: 2932.84 | GW8: 0 | GX8: 0 | GY8: 0 | GZ8: 2459.36 | HA8: 2337.456 | HB8: 3325 | HC8: 3420 | HD8: 0 | HE8: 0 | HF8: 0 | HG8: 1140 | HH8: 0 | HI8: 0 | HJ8: 324 | HK8: 0 | HL8: 3411.72 | HM8: 6917.724 | HN8: 6156 | HO8: 0 | HP8: 0 | HQ8: 5508 | HR8: 69922.44 | HS8: 62097.84 | HT8: 0 | HU8: 74844 | HV8: 32976.72 | HW8: 20412 | HX8: 19640.88 | HY8: 38556 | HZ8: 7604.28 | IA8: 0 | IB8: 0 | IC8: 0 | ID8: 0 | IE8: 5465.88 | IF8: 6612.84 | IG8: 0 | IH8: 18910.584 | II8: 6732.72 | IJ8: 12866.04 | IK8: 1944 | IL8: 7960.68 | IM8: 6139.8 | IN8: 13049.1 | IO8: 0 | IP8: 0 | IQ8: 0 | IR8: 0 | IS8: 0 | IT8: 2916 | IU8: 3400.056 | IV8: 0 | IW8: 0 | IX8: 0 | IY8: 0 | IZ8: 0 | JA8: 0 | JB8: 0 | JC8: 0 | JD8: 0 | JE8: 0 | JF8: 15577.92 | JG8: 0 | JH8: 0 | JI8: 0 | JJ8: 15628.95 | JK8: 0 | JL8: 0 | JM8: 0 | JN8: 10484.64 | JO8: 9059.04 | JP8: 14175 | JQ8: 14580 | JR8: 0 | JS8: 0 | JT8: 0 | JU8: 5346 | JV8: 0 | JW8: 0 | JX8: 129 | JY8: 0 | JZ8: 1358.37 | KA8: 3129.8625 | KB8: 3063.75 | KC8: 0 | KD8: 0 | KE8: 2741.25 | KF8: 27839.49 | KG8: 24724.14 | KH8: 0 | KI8: 29799 | KJ8: 13129.62 | KK8: 8127 | KL8: 7819.98 | KM8: 15351 | KN8: 3330.393 | KO8: 0 | KP8: 0 | KQ8: 0 | KR8: 0 | KS8: 2176.23 | KT8: 2632.89 | KU8: 0 | KV8: 6844.74 | KW8: 2680.62 | KX8: 6403.2375 | KY8: 774 | KZ8: 3169.53 | LA8: 2689.005 | LB8: 4156.38 | LC8: 0 | LD8: 0 | LE8: 0 | LF8: 0 | LG8: 0 | LH8: 1290 | LI8: 1230.66 | LJ8: 0 | LK8: 0 | LL8: 0 | LM8: 0 | LN8: 0 | LO8: 0 | LP8: 0 | LQ8: 0 | LR8: 0 | LS8: 0 | LT8: 6202.32 | LU8: 0 | LV8: 0 | LW8: 0 | LX8: 4978.11 | LY8: 0 | LZ8: 0 | MA8: 0 | MB8: 4174.44 | MC8: 3246.156 | MD8: 4515 | ME8: 5805 | MF8: 0 | MG8: 0 | MH8: 0 | MI8: 1741.5 | MJ8: 0 | MK8: 0 | ML8: 177 | MM8: 0 | MN8: 1863.81 | MO8: 3779.127 | MP8: 3363 | MQ8: 0 | MR8: 0 | MS8: 3009 | MT8: 38198.37 | MU8: 33923.82 | MV8: 0 | MW8: 40887 | MX8: 18015.06 | MY8: 11151 | MZ8: 10729.74 | NA8: 21063 | NB8: 4154.19 | NC8: 0 | ND8: 0 | NE8: 0 | NF8: 0 | NG8: 2985.99 | NH8: 3612.57 | NI8: 0 | NJ8: 9391.62 | NK8: 3310.254 | NL8: 6325.803 | NM8: 1062 | NN8: 4348.89 | NO8: 3018.735 | NP8: 5132.646 | NQ8: 0 | NR8: 0 | NS8: 0 | NT8: 0 | NU8: 0 | NV8: 2212.5 | NW8: 2110.725 | NX8: 0 | NY8: 0 | NZ8: 0 | OA8: 0 | OB8: 0 | OC8: 0 | OD8: 0 | OE8: 0 | OF8: 0 | OG8: 0 | OH8: 8510.16 | OI8: 0 | OJ8: 0 | OK8: 0 | OL8: 6830.43 | OM8: 0 | ON8: 0 | OO8: 0 | OP8: 5727.72 | OQ8: 4948.92 | OR8: 6195 | OS8: 7965 | OT8: 0 | OU8: 0 | OV8: 0 | OW8: 2389.5 | OX8: 0 | OY8: 0 | OZ8: 308 | PA8: 0 | PB8: 3243.24 | PC8: 5978.28 | PD8: 5852 | PE8: 0 | PF8: 0 | PG8: 5759.6 | PH8: 66469.48 | PI8: 59031.28 | PJ8: 0 | PK8: 71148 | PL8: 31348.24 | PM8: 19404 | PN8: 18670.96 | PO8: 36652 | PP8: 7228.76 | PQ8: 0 | PR8: 0 | PS8: 0 | PT8: 0 | PU8: 5195.96 | PV8: 7857.85 | PW8: 0 | PX8: 16342.48 | PY8: 8000.3 | PZ8: 12230.68 | QA8: 1848 | QB8: 7567.56 | QC8: 7295.75 | QD8: 9923.76 | QE8: 0 | QF8: 0 | QG8: 0 | QH8: 0 | QI8: 0 | QJ8: 2772 | QK8: 2938.32 | QL8: 0 | QM8: 0 | QN8: 0 | QO8: 0 | QP8: 0 | QQ8: 0 | QR8: 0 | QS8: 0 | QT8: 0 | QU8: 0 | QV8: 14808.64 | QW8: 0 | QX8: 0 | QY8: 0 | QZ8: 11885.72 | RA8: 0 | RB8: 0 | RC8: 0 | RD8: 9966.88 | RE8: 8611.68 | RF8: 10780 | RG8: 12474 | RH8: 0 | RI8: 0 | RJ8: 0 | RK8: 5775 | RL8: 0 | RM8: 0 | RN8: 186 | RO8: 0 | RP8: 1958.58 | RQ8: 3610.26 | RR8: 3180.6 | RS8: 0 | RT8: 0 | RU8: 3162 | RV8: 40140.66 | RW8: 35648.76 | RX8: 0 | RY8: 42966 | RZ8: 18931.08 | SA8: 11718 | SB8: 11275.32 | SC8: 22134 | SD8: 4365.42 | SE8: 0 | SF8: 0 | SG8: 0 | SH8: 0 | SI8: 3137.82 | SJ8: 3796.26 | SK8: 0 | SL8: 9869.16 | SM8: 3865.08 | SN8: 7386.06 | SO8: 1116 | SP8: 4570.02 | SQ8: 3524.7 | SR8: 5992.92 | SS8: 0 | ST8: 0 | SU8: 0 | SV8: 0 | SW8: 0 | SX8: 1674 | SY8: 1774.44 | SZ8: 0 | TA8: 0 | TB8: 0 | TC8: 0 | TD8: 0 | TE8: 0 | TF8: 0 | TG8: 0 | TH8: 0 | TI8: 0 | TJ8: 8942.88 | TK8: 0 | TL8: 0 | TM8: 0 | TN8: 7177.74 | TO8: 0 | TP8: 0 | TQ8: 0 | TR8: 7523.7 | TS8: 5200.56 | TT8: 5859 | TU8: 8370 | TV8: 0 | TW8: 0 | TX8: 0 | TY8: 2790 | TZ8: 0 | UA8: 0 | UB8: 242 | UC8: 0 | UD8: 2548.26 | UE8: 5166.942 | UF8: 4598 | UG8: 0 | UH8: 0 | UI8: 4114 | UJ8: 52226.02 | UK8: 46381.72 | UL8: 0 | UM8: 55902 | UN8: 24630.76 | UO8: 15246 | UP8: 14670.04 | UQ8: 28798 | UR8: 5111.766 | US8: 0 | UT8: 0 | UU8: 0 | UV8: 0 | UW8: 4490.794 | UX8: 4445.298 | UY8: 0 | UZ8: 11556.468 | VA8: 5028.76 | VB8: 9609.82 | VC8: 1306.8 | VD8: 5945.94 | VE8: 4585.9 | VF8: 7797.24 | VG8: 0 | VH8: 0 | VI8: 0 | VJ8: 0 | VK8: 0 | VL8: 2420 | VM8: 2308.68 | VN8: 0 | VO8: 0 | VP8: 0 | VQ8: 0 | VR8: 0 | VS8: 0 | VT8: 0 | VU8: 0 | VV8: 0 | VW8: 0 | VX8: 11635.36 | VY8: 0 | VZ8: 0 | WA8: 0 | WB8: 9338.78 | WC8: 0 | WD8: 0 | WE8: 0 | WF8: 7831.12 | WG8: 6766.32 | WH8: 10587.5 | WI8: 9801 | WJ8: 0 | WK8: 0 | WL8: 0 | WM8: 3630 | WN8: 0 | WO8: 0 | WP8: 62 | WQ8: 0 | WR8: 587.574 | WS8: 1203.42 | WT8: 1178 | WU8: 0 | WV8: 0 | WW8: 1054 | WX8: 13380.22 | WY8: 11882.92 | WZ8: 0 | XA8: 14322 | XB8: 6310.36 | XC8: 3906 | XD8: 3758.44 | XE8: 7378 | XF8: 1455.14 | XG8: 0 | XH8: 0 | XI8: 0 | XJ8: 0 | XK8: 1150.534 | XL8: 1265.42 | XM8: 0 | XN8: 3289.72 | XO8: 1288.36 | XP8: 2462.02 | XQ8: 372 | XR8: 1523.34 | XS8: 1468.625 | XT8: 1797.876 | XU8: 0 | XV8: 0 | XW8: 0 | XX8: 0 | XY8: 0 | XZ8: 620 | YA8: 739.35 | YB8: 0 | YC8: 0 | YD8: 0 | YE8: 0 | YF8: 0 | YG8: 0 | YH8: 0 | YI8: 0 | YJ8: 0 | YK8: 0 | YL8: 2980.96 | YM8: 0 | YN8: 0 | YO8: 0 | YP8: 2153.322 | YQ8: 0 | YR8: 0 | YS8: 0 | YT8: 1805.688 | YU8: 1733.52 | YV8: 2170 | YW8: 2790 | YX8: 0 | YY8: 0 | YZ8: 0 | ZA8: 1162.5 | ZB8: 0 | ZC8: 0 | ZD8: 59 | ZE8: 0 | ZF8: 621.27 | ZG8: 1145.19 | ZH8: 1121 | ZI8: 0 | ZJ8: 0 | ZK8: 1003 | ZL8: 12732.79 | ZM8: 11307.94 | ZN8: 0 | ZO8: 13629 | ZP8: 6005.02 | ZQ8: 3717 | ZR8: 3576.58 | ZS8: 7021 | ZT8: 1246.257 | ZU8: 0 | ZV8: 0 | ZW8: 0 | ZX8: 0 | ZY8: 995.33 | ZZ8: 1083.771 | AAA8: 0 | AAB8: 3443.594 | AAC8: 1532.525 | AAD8: 2108.601 | AAE8: 318.6 | AAF8: 1812.0375 | AAG8: 1118.05 | AAH8: 1900.98 | AAI8: 0 | AAJ8: 0 | AAK8: 0 | AAL8: 0 | AAM8: 0 | AAN8: 590 | AAO8: 562.86 | AAP8: 0 | AAQ8: 0 | AAR8: 0 | AAS8: 0 | AAT8: 0 | AAU8: 0 | AAV8: 0 | AAW8: 0 | AAX8: 0 | AAY8: 0 | AAZ8: 3545.9 | ABA8: 0 | ABB8: 0 | ABC8: 0 | ABD8: 2276.81 | ABE8: 0 | ABF8: 0 | ABG8: 0 | ABH8: 1909.24 | ABI8: 1649.64 | ABJ8: 1858.5 | ABK8: 2655 | ABL8: 0 | ABM8: 0 | ABN8: 0 | ABO8: 1106.25 | ABP8: 0 | ABQ8: 0 | ABR8: 249 | ABS8: 0 | ABT8: 2621.97 | ABU8: 4349.781 | ABV8: 4731 | ABW8: 0 | ABX8: 0 | ABY8: 4233 | ABZ8: 53736.69 | ACA8: 47723.34 | ACB8: 0 | ACC8: 57519 | ACD8: 25343.22 | ACE8: 15687 | ACF8: 15094.38 | ACG8: 29631 | ACH8: 5844.03 | ACI8: 0 | ACJ8: 0 | ACK8: 0 | ACL8: 0 | ACM8: 4200.63 | ACN8: 6352.6125 | ACO8: 0 | ACP8: 13211.94 | ACQ8: 5174.22 | ACR8: 9887.79 | ACS8: 1494 | ACT8: 6117.93 | ACU8: 4718.55 | ACV8: 8022.78 | ACW8: 0 | ACX8: 0 | ACY8: 0 | ACZ8: 0 | ADA8: 0 | ADB8: 2490 | ADC8: 2375.46 | ADD8: 0 | ADE8: 0 | ADF8: 0 | ADG8: 0 | ADH8: 0 | ADI8: 0 | ADJ8: 0 | ADK8: 0 | ADL8: 0 | ADM8: 0 | ADN8: 13169.112 | ADO8: 0 | ADP8: 0 | ADQ8: 0 | ADR8: 9608.91 | ADS8: 0 | ADT8: 0 | ADU8: 0 | ADV8: 7251.876 | ADW8: 6962.04 | ADX8: 8715 | ADY8: 12325.5 | ADZ8: 0 | AEA8: 0 | AEB8: 0 | AEC8: 3735 | AED8: 0 | AEE8: 0 | AEF8: 238 | AEG8: 0 | AEH8: 2506.14 | AEI8: 5081.538 | AEJ8: 4069.8 | AEK8: 0 | AEL8: 0 | AEM8: 5057.5 | AEN8: 51362.78 | AEO8: 45615.08 | AEP8: 0 | AEQ8: 54978 | AER8: 24223.64 | AES8: 14994 | AET8: 14427.56 | AEU8: 28322 | AEV8: 5027.274 | AEW8: 0 | AEX8: 0 | AEY8: 0 | AEZ8: 0 | AFA8: 4015.06 | AFB8: 5343.338 | AFC8: 0 | AFD8: 15785.35 | AFE8: 4945.64 | AFF8: 9450.98 | AFG8: 1428 | AFH8: 5847.66 | AFI8: 4961.11 | AFJ8: 7668.36 | AFK8: 0 | AFL8: 0 | AFM8: 0 | AFN8: 0 | AFO8: 0 | AFP8: 2380 | AFQ8: 2270.52 | AFR8: 0 | AFS8: 0 | AFT8: 0 | AFU8: 0 | AFV8: 0 | AFW8: 0 | AFX8: 0 | AFY8: 0 | AFZ8: 0 | AGA8: 0 | AGB8: 11443.04 | AGC8: 0 | AGD8: 0 | AGE8: 0 | AGF8: 8265.978 | AGG8: 0 | AGH8: 0 | AGI8: 0 | AGJ8: 9627.1 | AGK8: 6654.48 | AGL8: 9163 | AGM8: 11781 | AGN8: 0 | AGO8: 0 | AGP8: 0 | AGQ8: 3570 | AGR8: 0 | AGS8: 0 | AGU8: =IF($P8>0,CH8*$K8,0) -> 192 | AGV8: =IF($P8>0,EV8*$K8,0) -> 76 | AGW8: =IF($P8>0,HJ8*$K8,0) -> 324 | AGX8: =IF($P8>0,JX8*$K8,0) -> 129 | AGY8: =IF($P8>0,ML8*$K8,0) -> 177 | AGZ8: =IF($P8>0,OZ8*$K8,0) -> 308 | AHA8: =IF($P8>0,RN8*$K8,0) -> 186 | AHB8: =IF($P8>0,UB8*$K8,0) -> 242 | AHC8: =IF($P8>0,WP8*$K8,0) -> 62 | AHD8: =IF($P8>0,ZD8*$K8,0) -> 59 | AHE8: =IF($P8>0,ABR8*$K8,0) -> 249 | AHF8: =IF($P8>0,AEF8*$K8,0) -> 238
F9: ASSY-016 | H9: CH-002 | I9: part 2 | K9: 3 | L9: 12.7 | P9: 1 | R9: FMCNC2 | S9: HAND | Z9: 15.98 | AB9: 1.74 | AC9: 40.65 | AE9: 28.42 | AF9: 13 | AG9: 28.9 | AH9: 30.89 | AL9: 45.1 | AM9: 36.6 | AO9: 22.55 | AS9: 29 | AX9: 20.15 | AY9: 56.45 | AZ9: 44.65 | BA9: 24.02 | BC9: 18 | BE9: 40.06 | BG9: 28 | BI9: 57.41 | BQ9: 29 | BS9: 32 | BT9: 9 | BU9: 17.62 | BV9: 17 | BX9: 40.46 | BY9: 5.44 | CD9: 28 | CE9: 6.35 | CF9: 15.11 | CG9: 53.35 | CH9: 214 | CI9: 0 | CJ9: 0 | CK9: 0 | CL9: 0 | CM9: 0 | CN9: 3419.72 | CO9: 0 | CP9: 930.9 | CQ9: 21747.75 | CR9: 0 | CS9: 15204.7 | CT9: 13910 | CU9: 30923 | CV9: 33052.3 | CW9: 0 | CX9: 0 | CY9: 0 | CZ9: 9651.4 | DA9: 7832.4 | DB9: 0 | DC9: 4825.7 | DD9: 0 | DE9: 0 | DF9: 0 | DG9: 6206 | DH9: 0 | DI9: 0 | DJ9: 0 | DK9: 0 | DL9: 4743.31 | DM9: 12080.3 | DN9: 9555.1 | DO9: 5654.308 | DP9: 0 | DQ9: 3852 | DR9: 0 | DS9: 8572.84 | DT9: 0 | DU9: 5992 | DV9: 0 | DW9: 12285.74 | DX9: 0 | DY9: 0 | DZ9: 0 | EA9: 0 | EB9: 0 | EC9: 0 | ED9: 0 | EE9: 6206 | EF9: 0 | EG9: 6848 | EH9: 2407.5 | EI9: 3770.68 | EJ9: 3638 | EK9: 0 | EL9: 8658.44 | EM9: 1164.16 | EN9: 0 | EO9: 0 | EP9: 0 | EQ9: 0 | ER9: 7490 | ES9: 1358.9 | ET9: 3233.54 | EU9: 14271.125 | EV9: 273 | EW9: 0 | EX9: 0 | EY9: 0 | EZ9: 0 | FA9: 0 | FB9: 4362.54 | FC9: 0 | FD9: 1187.55 | FE9: 27743.625 | FF9: 0 | FG9: 19396.65 | FH9: 17745 | FI9: 39448.5 | FJ9: 42164.85 | FK9: 0 | FL9: 0 | FM9: 0 | FN9: 12312.3 | FO9: 8992.62 | FP9: 0 | FQ9: 6156.15 | FR9: 0 | FS9: 0 | FT9: 0 | FU9: 7125.3 | FV9: 0 | FW9: 0 | FX9: 0 | FY9: 0 | FZ9: 6051.045 | GA9: 16951.935 | GB9: 12189.45 | GC9: 6557.46 | GD9: 0 | GE9: 4914 | GF9: 0 | GG9: 10936.38 | GH9: 0 | GI9: 7644 | GJ9: 0 | GK9: 15672.93 | GL9: 0 | GM9: 0 | GN9: 0 | GO9: 0 | GP9: 0 | GQ9: 0 | GR9: 0 | GS9: 9896.25 | GT9: 0 | GU9: 8736 | GV9: 2457 | GW9: 6012.825 | GX9: 5105.1 | GY9: 0 | GZ9: 11045.58 | HA9: 1633.632 | HB9: 0 | HC9: 0 | HD9: 0 | HE9: 0 | HF9: 9555 | HG9: 1733.55 | HH9: 4125.03 | HI9: 14564.55 | HJ9: 189 | HK9: 0 | HL9: 0 | HM9: 0 | HN9: 0 | HO9: 0 | HP9: 3020.22 | HQ9: 0 | HR9: 822.15 | HS9: 19207.125 | HT9: 0 | HU9: 13428.45 | HV9: 12285 | HW9: 27310.5 | HX9: 29191.05 | HY9: 0 | HZ9: 0 | IA9: 0 | IB9: 9376.29 | IC9: 6917.4 | ID9: 0 | IE9: 4261.95 | IF9: 0 | IG9: 0 | IH9: 0 | II9: 5481 | IJ9: 0 | IK9: 0 | IL9: 0 | IM9: 0 | IN9: 4760.4375 | IO9: 10669.05 | IP9: 8438.85 | IQ9: 4539.78 | IR9: 0 | IS9: 3061.8 | IT9: 0 | IU9: 8328.474 | IV9: 0 | IW9: 5292 | IX9: 0 | IY9: 10850.49 | IZ9: 0 | JA9: 0 | JB9: 0 | JC9: 0 | JD9: 0 | JE9: 0 | JF9: 0 | JG9: 5481 | JH9: 0 | JI9: 6048 | JJ9: 2126.25 | JK9: 3330.18 | JL9: 3213 | JM9: 0 | JN9: 7646.94 | JO9: 1028.16 | JP9: 0 | JQ9: 0 | JR9: 0 | JS9: 0 | JT9: 5292 | JU9: 1320.165 | JV9: 2855.79 | JW9: 10083.15 | JX9: 312 | JY9: 0 | JZ9: 0 | KA9: 0 | KB9: 0 | KC9: 0 | KD9: 4985.76 | KE9: 0 | KF9: 1357.2 | KG9: 31707 | KH9: 0 | KI9: 22167.6 | KJ9: 20280 | KK9: 45084 | KL9: 48188.4 | KM9: 0 | KN9: 0 | KO9: 0 | KP9: 15478.32 | KQ9: 11419.2 | KR9: 0 | KS9: 7035.6 | KT9: 0 | KU9: 0 | KV9: 0 | KW9: 9048 | KX9: 0 | KY9: 0 | KZ9: 0 | LA9: 0 | LB9: 6286.8 | LC9: 17612.4 | LD9: 13930.8 | LE9: 8243.664 | LF9: 0 | LG9: 5616 | LH9: 0 | LI9: 12498.72 | LJ9: 0 | LK9: 8736 | LL9: 0 | LM9: 17911.92 | LN9: 0 | LO9: 0 | LP9: 0 | LQ9: 0 | LR9: 0 | LS9: 0 | LT9: 0 | LU9: 9048 | LV9: 0 | LW9: 9984 | LX9: 2808 | LY9: 5497.44 | LZ9: 4773.6 | MA9: 0 | MB9: 12623.52 | MC9: 1527.552 | MD9: 0 | ME9: 0 | MF9: 0 | MG9: 0 | MH9: 8736 | MI9: 1783.08 | MJ9: 5892.9 | MK9: 14980.68 | ML9: 289 | MM9: 0 | MN9: 0 | MO9: 0 | MP9: 0 | MQ9: 0 | MR9: 4618.22 | MS9: 0 | MT9: 1257.15 | MU9: 29369.625 | MV9: 0 | MW9: 20533.45 | MX9: 18785 | MY9: 41760.5 | MZ9: 44636.05 | NA9: 0 | NB9: 0 | NC9: 0 | ND9: 13033.9 | NE9: 10577.4 | NF9: 0 | NG9: 6516.95 | NH9: 0 | NI9: 0 | NJ9: 0 | NK9: 7542.9 | NL9: 0 | NM9: 0 | NN9: 0 | NO9: 0 | NP9: 5241.015 | NQ9: 16314.05 | NR9: 12903.85 | NS9: 6941.78 | NT9: 0 | NU9: 5202 | NV9: 0 | NW9: 14471.675 | NX9: 0 | NY9: 8092 | NZ9: 0 | OA9: 16591.49 | OB9: 0 | OC9: 0 | OD9: 0 | OE9: 0 | OF9: 0 | OG9: 0 | OH9: 0 | OI9: 9219.1 | OJ9: 0 | OK9: 9248 | OL9: 2601 | OM9: 4582.962 | ON9: 4913 | OO9: 0 | OP9: 11692.94 | OQ9: 1572.16 | OR9: 0 | OS9: 0 | OT9: 0 | OU9: 0 | OV9: 8092 | OW9: 1651.635 | OX9: 3930.111 | OY9: 15418.15 | OZ9: 163 | PA9: 0 | PB9: 0 | PC9: 0 | PD9: 0 | PE9: 0 | PF9: 2604.74 | PG9: 0 | PH9: 709.05 | PI9: 16564.875 | PJ9: 0 | PK9: 11581.15 | PL9: 10595 | PM9: 23553.5 | PN9: 25175.35 | PO9: 0 | PP9: 0 | PQ9: 0 | PR9: 7351.3 | PS9: 5965.8 | PT9: 0 | PU9: 3675.65 | PV9: 0 | PW9: 0 | PX9: 0 | PY9: 5908.75 | PZ9: 0 | QA9: 0 | QB9: 0 | QC9: 0 | QD9: 3284.45 | QE9: 9201.35 | QF9: 6550.155 | QG9: 3915.26 | QH9: 0 | QI9: 3227.4 | QJ9: 0 | QK9: 6529.78 | QL9: 0 | QM9: 5020.4 | QN9: 0 | QO9: 10293.613 | QP9: 0 | QQ9: 0 | QR9: 0 | QS9: 0 | QT9: 0 | QU9: 0 | QV9: 0 | QW9: 4727 | QX9: 0 | QY9: 5216 | QZ9: 1467 | RA9: 2872.06 | RB9: 2493.9 | RC9: 0 | RD9: 6594.98 | RE9: 886.72 | RF9: 0 | RG9: 0 | RH9: 0 | RI9: 0 | RJ9: 4564 | RK9: 1293.8125 | RL9: 2462.93 | RM9: 9565.655 | RN9: 64 | RO9: 0 | RP9: 0 | RQ9: 0 | RR9: 0 | RS9: 0 | RT9: 1022.72 | RU9: 0 | RV9: 278.4 | RW9: 6504 | RX9: 0 | RY9: 4547.2 | RZ9: 4160 | SA9: 9248 | SB9: 9884.8 | SC9: 0 | SD9: 0 | SE9: 0 | SF9: 2886.4 | SG9: 2342.4 | SH9: 0 | SI9: 1443.2 | SJ9: 0 | SK9: 0 | SL9: 0 | SM9: 1856 | SN9: 0 | SO9: 0 | SP9: 0 | SQ9: 0 | SR9: 1289.6 | SS9: 4516 | ST9: 2857.6 | SU9: 1537.28 | SV9: 0 | SW9: 1152 | SX9: 0 | SY9: 2563.84 | SZ9: 0 | TA9: 1792 | TB9: 0 | TC9: 3674.24 | TD9: 0 | TE9: 0 | TF9: 0 | TG9: 0 | TH9: 0 | TI9: 0 | TJ9: 0 | TK9: 2320 | TL9: 0 | TM9: 2048 | TN9: 576 | TO9: 1127.68 | TP9: 1088 | TQ9: 0 | TR9: 3236.8 | TS9: 348.16 | TT9: 0 | TU9: 0 | TV9: 0 | TW9: 0 | TX9: 1792 | TY9: 406.4 | TZ9: 967.04 | UA9: 3414.4 | UB9: 353 | UC9: 0 | UD9: 0 | UE9: 0 | UF9: 0 | UG9: 0 | UH9: 5640.94 | UI9: 0 | UJ9: 1535.55 | UK9: 35873.625 | UL9: 0 | UM9: 25080.65 | UN9: 22945 | UO9: 51008.5 | UP9: 54520.85 | UQ9: 0 | UR9: 0 | US9: 0 | UT9: 15920.3 | UU9: 12919.8 | UV9: 0 | UW9: 8756.165 | UX9: 0 | UY9: 0 | UZ9: 0 | VA9: 10237 | VB9: 0 | VC9: 0 | VD9: 0 | VE9: 0 | VF9: 7112.95 | VG9: 17934.165 | VH9: 15761.45 | VI9: 8479.06 | VJ9: 0 | VK9: 6354 | VL9: 0 | VM9: 14141.18 | VN9: 0 | VO9: 8895.6 | VP9: 0 | VQ9: 20265.73 | VR9: 0 | VS9: 0 | VT9: 0 | VU9: 0 | VV9: 0 | VW9: 0 | VX9: 0 | VY9: 10237 | VZ9: 0 | WA9: 11296 | WB9: 3177 | WC9: 6219.86 | WD9: 6001 | WE9: 0 | WF9: 14282.38 | WG9: 1920.32 | WH9: 0 | WI9: 0 | WJ9: 0 | WK9: 0 | WL9: 9884 | WM9: 2241.55 | WN9: 5333.83 | WO9: 18832.55 | WP9: 263 | WQ9: 0 | WR9: 0 | WS9: 0 | WT9: 0 | WU9: 0 | WV9: 4202.74 | WW9: 0 | WX9: 1144.05 | WY9: 26727.375 | WZ9: 0 | XA9: 18686.15 | XB9: 17095 | XC9: 38003.5 | XD9: 40620.35 | XE9: 0 | XF9: 0 | XG9: 0 | XH9: 11861.3 | XI9: 12032.25 | XJ9: 0 | XK9: 6523.715 | XL9: 0 | XM9: 0 | XN9: 0 | XO9: 7627 | XP9: 0 | XQ9: 0 | XR9: 0 | XS9: 0 | XT9: 4769.505 | XU9: 14846.35 | XV9: 10568.655 | XW9: 6317.26 | XX9: 0 | XY9: 4734 | XZ9: 0 | YA9: 13169.725 | YB9: 0 | YC9: 9205 | YD9: 0 | YE9: 15098.83 | YF9: 0 | YG9: 0 | YH9: 0 | YI9: 0 | YJ9: 0 | YK9: 0 | YL9: 0 | YM9: 6864.3 | YN9: 0 | YO9: 8416 | YP9: 2130.3 | YQ9: 4634.06 | YR9: 4471 | YS9: 0 | YT9: 9576.882 | YU9: 1430.72 | YV9: 0 | YW9: 0 | YX9: 0 | YY9: 0 | YZ9: 8100.4 | ZA9: 2087.5625 | ZB9: 3973.93 | ZC9: 14031.05 | ZD9: 316 | ZE9: 0 | ZF9: 0 | ZG9: 0 | ZH9: 0 | ZI9: 0 | ZJ9: 5049.68 | ZK9: 0 | ZL9: 1374.6 | ZM9: 32113.5 | ZN9: 0 | ZO9: 22451.8 | ZP9: 20540 | ZQ9: 45662 | ZR9: 48806.2 | ZS9: 0 | ZT9: 0 | ZU9: 0 | ZV9: 14251.6 | ZW9: 11565.6 | ZX9: 0 | ZY9: 7125.8 | ZZ9: 0 | AAA9: 0 | AAB9: 0 | AAC9: 11455 | AAD9: 0 | AAE9: 0 | AAF9: 0 | AAG9: 0 | AAH9: 6367.4 | AAI9: 19622.02 | AAJ9: 17636.75 | AAK9: 7590.32 | AAL9: 0 | AAM9: 5688 | AAN9: 0 | AAO9: 12658.96 | AAP9: 0 | AAQ9: 8848 | AAR9: 0 | AAS9: 18141.56 | AAT9: 0 | AAU9: 0 | AAV9: 0 | AAW9: 0 | AAX9: 0 | AAY9: 0 | AAZ9: 0 | ABA9: 9164 | ABB9: 0 | ABC9: 10112 | ABD9: 2844 | ABE9: 5567.92 | ABF9: 6715 | ABG9: 0 | ABH9: 12785.36 | ABI9: 1719.04 | ABJ9: 0 | ABK9: 0 | ABL9: 0 | ABM9: 0 | ABN9: 8848 | ABO9: 2508.25 | ABP9: 4774.76 | ABQ9: 16858.6 | ABR9: 335 | ABS9: 0 | ABT9: 0 | ABU9: 0 | ABV9: 0 | ABW9: 0 | ABX9: 5353.3 | ABY9: 0 | ABZ9: 1457.25 | ACA9: 34044.375 | ACB9: 0 | ACC9: 23801.75 | ACD9: 21775 | ACE9: 48407.5 | ACF9: 51740.75 | ACG9: 0 | ACH9: 0 | ACI9: 0 | ACJ9: 16619.35 | ACK9: 13487.1 | ACL9: 0 | ACM9: 7554.25 | ACN9: 0 | ACO9: 0 | ACP9: 0 | ACQ9: 9715 | ACR9: 0 | ACS9: 0 | ACT9: 0 | ACU9: 0 | ACV9: 6750.25 | ACW9: 17019.675 | ACX9: 16453.525 | ACY9: 7242.03 | ACZ9: 0 | ADA9: 6030 | ADB9: 0 | ADC9: 13420.1 | ADD9: 0 | ADE9: 11725 | ADF9: 0 | ADG9: 19232.35 | ADH9: 0 | ADI9: 0 | ADJ9: 0 | ADK9: 0 | ADL9: 0 | ADM9: 0 | ADN9: 0 | ADO9: 9715 | ADP9: 0 | ADQ9: 11792 | ADR9: 3015 | ADS9: 5902.7 | ADT9: 5695 | ADU9: 0 | ADV9: 12198.69 | ADW9: 1822.4 | ADX9: 0 | ADY9: 0 | ADZ9: 0 | AEA9: 0 | AEB9: 9380 | AEC9: 2127.25 | AED9: 6327.3125 | AEE9: 17872.25 | AEF9: 346 | AEG9: 0 | AEH9: 0 | AEI9: 0 | AEJ9: 0 | AEK9: 0 | AEL9: 5529.08 | AEM9: 0 | AEN9: 1505.1 | AEO9: 35162.25 | AEP9: 0 | AEQ9: 24583.3 | AER9: 22490 | AES9: 49997 | AET9: 53439.7 | AEU9: 0 | AEV9: 0 | AEW9: 0 | AEX9: 19505.75 | AEY9: 12663.6 | AEZ9: 0 | AFA9: 7802.3 | AFB9: 0 | AFC9: 0 | AFD9: 0 | AFE9: 10034 | AFF9: 0 | AFG9: 0 | AFH9: 0 | AFI9: 0 | AFJ9: 6971.9 | AFK9: 19531.7 | AFL9: 15448.9 | AFM9: 8310.92 | AFN9: 0 | AFO9: 6228 | AFP9: 0 | AFQ9: 13860.76 | AFR9: 0 | AFS9: 9688 | AFT9: 0 | AFU9: 19863.86 | AFV9: 0 | AFW9: 0 | AFX9: 0 | AFY9: 0 | AFZ9: 0 | AGA9: 0 | AGB9: 0 | AGC9: 10034 | AGD9: 0 | AGE9: 11072 | AGF9: 2802.6 | AGG9: 5486.868 | AGH9: 5882 | AGI9: 0 | AGJ9: 17498.95 | AGK9: 1882.24 | AGL9: 0 | AGM9: 0 | AGN9: 0 | AGO9: 0 | AGP9: 9688 | AGQ9: 2197.1 | AGR9: 4705.254 | AGS9: 20305.01 | AGU9: =IF($P9>0,CH9*$K9,0) -> 642 | AGV9: =IF($P9>0,EV9*$K9,0) -> 819 | AGW9: =IF($P9>0,HJ9*$K9,0) -> 567 | AGX9: =IF($P9>0,JX9*$K9,0) -> 936 | AGY9: =IF($P9>0,ML9*$K9,0) -> 867 | AGZ9: =IF($P9>0,OZ9*$K9,0) -> 489 | AHA9: =IF($P9>0,RN9*$K9,0) -> 192 | AHB9: =IF($P9>0,UB9*$K9,0) -> 1059 | AHC9: =IF($P9>0,WP9*$K9,0) -> 789 | AHD9: =IF($P9>0,ZD9*$K9,0) -> 948 | AHE9: =IF($P9>0,ABR9*$K9,0) -> 1005 | AHF9: =IF($P9>0,AEF9*$K9,0) -> 1038
